Workbook
Name AB: [1]BASE!$A$1:$IV$65536
Name ABC: [1]BASE1!$A$1:$IV$65536
Name ABVF: [1]GRADO1!$A$1:$IV$65536
Name Rango1: '[2]Matriz de Peligros'!$CG$495:$CH$505
Name Rango2: '[2]Matriz de Peligros'!$CJ$495:$CL$517
Name CONSE: #REF!
Name PROBAB: #REF!
Name NLESION: #REF!
Name CONSE: #REF!
Name PROBAB: #REF!
Name EXPOSI: #REF!
Name ABCD: #REF!
Name NATURALEZA_DE_LA_LESION: #REF!
Name NLESION: #REF!
Name EXPOSI: #REF!
Name ABCD: #REF!
Name NATURALEZA_DE_LA_LESION: #REF!

Sheet MAPA
A1: LOGO DEL PST | C1: NOMBRE DEL PST | D1: MAPA DE RIESGOS Y OPORTUNIDADES | V1: CÓDIGO:
V2: VERSIÓN:
A4: Mapa de riesgos y oportunidades | D4: Organizacional | G4: ACTIVIDAD DE TURISMO DE AVENTURA
A6: IDENTIFICACIÓN | K6: EVALUACIÓN | O6: TRATAMIENTO | S6: SEGUIMIENTO Y EVALUACIÓN
A7: FECHA | B7: PROCESO | C7: ACTIVIDADES ESPECÍFICAS / PROCEDIMIENTO | D7: TIPO DE SITUACIÓN | E7: FUENTE DEL RIESGO / OPORTUNIDAD | F7: DESCRIPCIÓN DEL RIESGO / OPORTUNIDAD | G7: CAUSAS PROBABLES DEL RIESGO O FACTORES QUE FAVORECEN LA OPORTUNIDAD | H7: CLASIFICACIÓN DEL RIESGO / OPORTUNIDAD | I7: CONSECUENCIAS O EFECTOS DEL RIESGO / OPORTUNIDAD | J7: CONTROLES EXISTENTES (SI EXISTEN) | K7: VALORACIÓN RIESGO / OPORTUNIDAD | O7: OPCIONES DE MANEJO | P7: ACCIONES | Q7: RESPONSABLE | R7: FECHA LÍMITE | S7: FECHA DE SEGUIMIENTO | T7: DESCRIBIR EL AVANCE Y ESTADO ACTUAL DE LAS ACCIONES | U7: RESULTADO ALCANZADO | V7: EFICAZ | X7: OBSERVACIONES
K8: PROBABILIDAD | L8: IMPACTO | M8: VALORACIÓN | N8: EVALUACIÓN RIESGO U OPORTUNIDAD | V8: SI | W8: NO
M9: =+K9*L9 -> 0 | N9: =VLOOKUP(M9,CRITERIOS!$A$45:$C$72,2,TRUE) -> BAJO | O9: =VLOOKUP(M9,CRITERIOS!$A$45:$C$72,3,TRUE) -> Asumir
M10: =+K10*L10 -> 0 | N10: =VLOOKUP(M10,CRITERIOS!$A$45:$C$72,2,TRUE) -> BAJO | O10: =VLOOKUP(M10,CRITERIOS!$A$45:$C$72,3,TRUE) -> Asumir
M11: =+K11*L11 -> 0 | N11: =VLOOKUP(M11,CRITERIOS!$A$45:$C$72,2,TRUE) -> BAJO | O11: =VLOOKUP(M11,CRITERIOS!$A$45:$C$72,3,TRUE) -> Asumir
M12: =+K12*L12 -> 0 | N12: =VLOOKUP(M12,CRITERIOS!$A$45:$C$72,2,TRUE) -> BAJO | O12: =VLOOKUP(M12,CRITERIOS!$A$45:$C$72,3,TRUE) -> Asumir
M13: =+K13*L13 -> 0 | N13: =VLOOKUP(M13,CRITERIOS!$A$45:$C$72,2,TRUE) -> BAJO | O13: =VLOOKUP(M13,CRITERIOS!$A$45:$C$72,3,TRUE) -> Asumir
M14: =+K14*L14 -> 0 | N14: =VLOOKUP(M14,CRITERIOS!$A$45:$C$72,2,TRUE) -> BAJO | O14: =VLOOKUP(M14,CRITERIOS!$A$45:$C$72,3,TRUE) -> Asumir
M15: =+K15*L15 -> 0 | N15: =VLOOKUP(M15,CRITERIOS!$A$45:$C$72,2,TRUE) -> BAJO | O15: =VLOOKUP(M15,CRITERIOS!$A$45:$C$72,3,TRUE) -> Asumir
M16: =+K16*L16 -> 0 | N16: =VLOOKUP(M16,CRITERIOS!$A$45:$C$72,2,TRUE) -> BAJO | O16: =VLOOKUP(M16,CRITERIOS!$A$45:$C$72,3,TRUE) -> Asumir
M17: =+K17*L17 -> 0 | N17: =VLOOKUP(M17,CRITERIOS!$A$45:$C$72,2,TRUE) -> BAJO | O17: =VLOOKUP(M17,CRITERIOS!$A$45:$C$72,3,TRUE) -> Asumir
M18: =+K18*L18 -> 0 | N18: =VLOOKUP(M18,CRITERIOS!$A$45:$C$72,2,TRUE) -> BAJO | O18: =VLOOKUP(M18,CRITERIOS!$A$45:$C$72,3,TRUE) -> Asumir
M19: =+K19*L19 -> 0 | N19: =VLOOKUP(M19,CRITERIOS!$A$45:$C$72,2,TRUE) -> BAJO | O19: =VLOOKUP(M19,CRITERIOS!$A$45:$C$72,3,TRUE) -> Asumir
M20: =+K20*L20 -> 0 | N20: =VLOOKUP(M20,CRITERIOS!$A$45:$C$72,2,TRUE) -> BAJO | O20: =VLOOKUP(M20,CRITERIOS!$A$45:$C$72,3,TRUE) -> Asumir
... M27: =+K27*L27 -> 0 | N27: =VLOOKUP(M27,CRITERIOS!$A$45:$C$72,2,TRUE) -> BAJO | O27: =VLOOKUP(M27,CRITERIOS!$A$45:$C$72,3,TRUE) -> Asumir

Sheet CRITERIOS
A1: LOGO DEL PST | C1: NOMBRE DEL PST | D1: CRITERIOS | K1: CÓDIGO:
K2: VERSIÓN:
A4: TABLA DE PROBABILIDAD | F4: TABLA DE IMPACTO PARA RIESGOS | J4: TABLA DE IMPACTO PARA OPORTUNIDADES
A5: NIVEL | B5: DESCRIPTOR | C5: DESCRIPCIÓN (FACTIBILIDAD) | D5: FRECUENCIA | F5: NIVEL | G5: DESCRIPTOR | H5: DESCRIPCIÓN | J5: NIVEL | K5: DESCRIPTOR | L5: DESCRIPCIÓN
A6: 2 | B6: RARO | C6: El evento puede ocurrir solo en circunstancias excepcionales | D6: No se ha presentado en los últimos 5 años. | F6: -2 | G6: Insignificante | H6: Si el hecho llegara a presentarse, tendría consecuencias o efectos mínimos sobre la organización. | J6: 2 | K6: Favorecedor | L6: Si el hecho pudiera lograrse, representaría un impacto favorecedor en los intereses de la organización.
A7: 4 | B7: IMPROBABLE | C7: El evento puede ocurrir en algún momento. | D7: Al menos de 1 vez en los últimos 5 años. | F7: -4 | G7: Menor | H7: Si el hecho llegara a presentarse, tendría bajo impacto o efecto sobre la organización. | J7: 4 | K7: Deseable | L7: Si el hecho pudiera lograrse, representaría un impacto deseable en los intereses de la organización.
A8: 6 | B8: POSIBLE | C8: El evento podría ocurrir en algún momento. | D8: Al menos de 1 vez en los últimos 2 años. | F8: -6 | G8: Moderado | H8: Si el hecho llegara a presentarse, tendría medianas consecuencias o efectos sobre la organización. | J8: 6 | K8: Positivo | L8: Si el hecho pudiera lograrse, representaría un impacto positivo en el logro de los objetivos de la organización.
A9: 8 | B9: PROBABLE | C9: El evento probablemente ocurrirá en la mayoría de las circunstancias. | D9: Al menos de 1 vez en el último año. | F9: -8 | G9: Mayor | H9: Si el hecho llegara a presentarse, tendría altas consecuencias o efectos sobre la organización. | J9: 8 | K9: Muy positivo | L9: Si el hecho pudiera lograrse, representaría un impacto muy positivo en el logro de los objetivos de la organización.
A10: 10 | B10: CASI SEGURO | C10: Se espera que el evento ocurra en la mayoría de las circunstancias. | D10: Más de 1 vez al año. | F10: -10 | G10: Catastrófico | H10: si el hecho llegara a presentarse, tendría desastrosas consecuencias o efectos sobre la organización. | J10: 10 | K10: Extraordinario | L10: Si el hecho pudiera lograrse, representaría una oportunidad extraordinaria para el logro de los objetivos de la organización.
D13: TABLA DE VALORACIÓN DE RIESGOS / OPORTUNIDADES
D14: PROBABILIDAD | K14: ACCIONES PARA OPORTUNIDADES
D15: Raro | E15: Improbable | F15: Posible | G15: Probable | H15: Casi cierto | K15: DESCRIPCIÓN | L15: DESCRIPCIÓN
D16: 2 | E16: 4 | F16: 6 | G16: 8 | H16: 10 | K16: MARAVILLOSA | L16: Implementar plan
A17: IMPACTO | B17: Extraordinario | C17: 10 | D17: Buena | E17: Atractiva | F17: Maravillosa | G17: Maravillosa | H17: Maravillosa | I17: OPORTUNIDADES | K17: ATRACTIVA | L17: Definir plan
D18: 20 | E18: 40 | F18: 60 | G18: 80 | H18: 100 | K18: BUENA | L18: Evaluar costo / beneficio
B19: Muy positivo | C19: 8 | D19: Retadora | E19: Buena | F19: Atractiva | G19: Maravillosa | H19: Maravillosa | K19: RETADORA | L19: Considerar
D20: 16 | E20: 32 | F20: 48 | G20: 64 | H20: 80
B21: Positivo | C21: 6 | D21: Retadora | E21: Buena | F21: Buena | G21: Atractiva | H21: Maravillosa | K21: ACCIONES PARA RIESGOS
D22: 12 | E22: 24 | F22: 36 | G22: 48 | H22: 60 | K22: DESCRIPCIÓN | L22: DESCRIPCIÓN
B23: Deseable | C23: 4 | D23: Retadora | E23: Retadora | F23: Buena | G23: Buena | H23: Atractiva | K23: BAJO | L23: Asumir el riesgo
D24: 8 | E24: 16 | F24: 24 | G24: 32 | H24: 40 | K24: MODERADO | L24: Asumir / reducir el riesgo
B25: Favorecedor | C25: 2 | D25: Retadora | E25: Retadora | F25: Retadora | G25: Retadora | H25: Buena | K25: ALTO | L25: Reducir, evitar, transferir el riesgo
D26: 4 | E26: 8 | F26: 12 | G26: 16 | H26: 20 | K26: EXTREMO | L26: Evitar, reducir, transferir el riesgo
B27: Insignificante | C27: -2 | D27: Bajo | E27: Bajo | F27: Bajo | G27: Bajo | H27: Moderado | I27: RIESGOS
D28: -4 | E28: -8 | F28: -12 | G28: -16 | H28: -20
B29: Menor | C29: -4 | D29: Bajo | E29: Bajo | F29: Moderado | G29: Moderado | H29: Alto
D30: -8 | E30: -16 | F30: -24 | G30: -32 | H30: -40
B31: Moderado | C31: -6 | D31: Bajo | E31: Moderado | F31: Moderado | G31: Alto | H31: Extremo
D32: -12 | E32: -24 | F32: -36 | G32: -48 | H32: -60
B33: Mayor | C33: -8 | D33: Bajo | E33: Moderado | F33: Alto | G33: Extremo | H33: Extremo
D34: -16 | E34: -32 | F34: -48 | G34: -64 | H34: -80
B35: Catastrófico | C35: -10 | D35: Moderado | E35: Alto | F35: Extremo | G35: Extremo | H35: Extremo
D36: -20 | E36: -40 | F36: -60 | G36: -80 | H36: -100
A45: -100 | B45: EXTREMO | C45: Evitar, Reducir, Transferir | E45: RIESGO | F45: OPORTUNIDAD | H45: Color | I45: HEX
A46: -80 | B46: EXTREMO | C46: Evitar, Reducir, Transferir | E46: -2 | F46: 2 | H46: EXTREMO | I46: #FC0B0F
A47: -64 | B47: EXTREMO | C47: Evitar, Reducir, Transferir | E47: -4 | F47: 4 | H47: EXTREMO | I47: #FC0B0F
A48: -60 | B48: EXTREMO | C48: Evitar, Reducir, Transferir | E48: -6 | F48: 6 | H48: EXTREMO | I48: #FC0B0F
A49: -48 | B49: ALTO | C49: Reducir, Evitar, Transferir | E49: -8 | F49: 8 | H49: EXTREMO | I49: #FC0B0F
A50: -40 | B50: ALTO | C50: Reducir, Evitar, Transferir | E50: -10 | F50: 10 | H50: ALTO | I50: #FF5901
A51: -36 | B51: MODERADO | C51: Asumir / reducir | H51: ALTO | I51: #FF5901
...

Sheet BD
A5: TIPO DE SITUACIÓN | B5: FUENTE | D5: CLASIFICACIÓN DEL RIESGO / OPORTUNIDAD | E5: TIPO DE MAPA | F5: ACTIVIDAD DE TURISMO DE AVENTURA
A6: Riesgo | D6: Ambientales | E6: Organizacional | F6: Canyoning
A7: Oportunidad | B7: Alcance del sistema de gestión | D7: Ciberseguridad | E7: Actividad de turismo de aventura | F7: Buceo
B8: Cambios en la organización | D8: De infraestructra (instalaciones y equipos) | F8: Rafting
B9: Contexto organizacional | D9: Económicos y financieros. | F9: Cabalgatas
B10: Desempeño de proceso / producto / servicio | D10: Gastronómicos o de seguridad alimentaria | F10: Espeleología
B11: No conformidades | D11: Médicos | F11: Rapel
B12: Reportes climáticos | D12: Operativos (seguridad en la operación de los servicios turísticos) | F12: Parapente
B13: Requisitos de las partes interesadas | D13: Organizacionales
B14: Requisitos legales y otros requisitos | D14: Públicos
B15: Otra ¿Cuál? | D15: Seguridad en aglomeraciones de público.
D16: Seguridad en la información
D17: Seguridad para las personas con discapacidad y otras personas con requisitos específicos de acceso
D18: Seguridad vial y de transporte.
D19: Sociales

Sheet TABLA CLASIFICACIÓN
A1: LOGO PST | E1: NOMBRE PST | G1: TABLA CLASIFICACIÓN DE RIESGOS | M1: CÓDIGO
M3: VERSIÓN
B6: CLASIFICACIÓN
B7: Ambientales (incluye climáticos) | C7: Públicos | D7: Médicos o de salud | E7: Sociales | F7: Seguridad en la información | G7: Ciberseguridad | H7: Económicos y financieros. | I7: Seguridad en aglomeraciones de público. | J7: Operativos (seguridad en la operación de los servicios turísticos) | K7: Organizacionales | L7: Gastronómicos o de seguridad alimentaria | M7: Seguridad vial y de transporte | N7: De infraestructura (instalaciones y equipos) | O7: Seguridad para las personas con discapacidad y otras personas con requisitos específicos de acceso
A8: POSIBLES RIESGOS | B8: Presencia de vectores en establecimientos | C8: Atentados | D8: Manejo de los grupos de participantes o clientes (Integración, trabajo en equipo) | E8: Drogadicción y alcoholismo en destinos y/o actividades turísticas | F8: Pérdida de la información | G8: Hackeo de información | H8: Crisis financiera | I8: Asfixia | J8: Falta de promoción del destino | K8: Gestión organizacional (Estilo de mando, contratación, bienestar social, trabajo bajo presión) | L8: Contaminación de producto | M8: Factor humano: | N8: Estado de Oficinas o sedes | O8: Medios de comunicación no aptos para personas con discapacidad
B9: Falta de cobertura y acceso de agua en zonas rurales y urbanas | C9: ⁠Robos / atracos | D9: Condiciones de salud por parte de los clientes, requeridas para la ejecución del servicio. | E9: Informalidad por falta de oportunidades de empleo | F9: Falla del canal de Internet o canales de telecomunicaciones dedicados a los clientes | G9: Ataques de phishing, spam, social media, para acceder a información | H9: Costos del negocio | I9: Comportamiento de las personas ante estímulos externos e internos | J9: La contaminación y degradación del entorno | K9: Estrategias | L9: Incumplimiento de especificaciones de producto | M9: Exceso del límite máximo de velocidad | N9: Estado eléctrico (Alta, media o baja tensión) | O9: Turismo accesible
B10: Contaminación del aire, suelo, recurso hídrico. | C10: Secuestros | D10: Pánico o ansiedad o desmayo | E10: Incremento de migración. | F10: Uso de software no licenciado | G10: Falsedad de identidad en redes como PST hacia clientes | H10: Presupuesto financiero y de ventas | I10: Condiciones del lugar o escenario que agrupa las personas | J10: No dominio de un segundo idioma | K10: Continuidad del negocio | L10: Estado refrigeración | M10: Consumo de alcohol o sustancias psicoactivas antes o durante la conducción | N10: Parque automotor | O10: Accesibilidad para colaboradores
B11: Aumento o escasez de lluvias | C11: ⁠Delincuencia común | D11: Enfermedades virales en el área donde se presta el servicio. | E11: Trabajo infantil y ESCNNA | F11: Gastos no planificados de mantenimiento por falta de soporte de equipos | G11: Uso inadecuado de inteligencia artificial | H11: Lavado de activos | I11: Aforo del evento | J11: La falta de divulgación de las medidas preventivas que deben tomar los visitantes, huéspedes y/o clientes | K11: Afectación de unidad de negocio | L11: Insatisfacción de consumidores del producto consumido | M11: Sueño o fatiga | N11: Estado de equipos de prestación del servicio | O11: Adaptación del servicio para accesibilidad de personas con discapacidad
B12: Incremento de sequías | C12: Marchas / manifestaciones | D12: Pandemias | E12: Apoyo insuficiente a población vulnerable por falta de programas de los municipios. | F12: Fuga de información confidencial del cliente | H12: Acuerdos con grupos al margen de la ley | I12: Perfil demográfico de los asistentes o participantes | J12: Calificación del servicio: por sobrecarga del lugar, Higiene y seguridad - ocurrencia de accidentes (visitantes, huéspedes y/o clientes), intoxicaciones (clientes - sector gastronómico) | L12: Afectación de la salud de los consumidores | M12: Uso de equipos bidireccionales | N12: Estado dotación maquinaria o herramientas | O12: Falta de formación a colaboradores para manejo de medios de apoyo para atender personas con discapacidad
B13: Condiciones meteorológica y del agua Crecientes, inundaciones de fuentes hídricas (ríos, quebradas) | D13: Consumo de sustancias alucinógenas o bebidas alcohólicas | E13: Mendicidad | F13: Contraseñas compartidas a varias personas y con débil control a plataformas | I13: Amenazas de origen natural, o antrópicas que pueden materializarse durante la actividad. | J13: Inconvenientes con proveedores | L13: Estado o trazabilidad de materias primas | M13: Exceso de confianza | N13: Estado EPP y equipos de rescate o seguridad | O13: Adecuación de infraestructura para accesibilidad
B14: Cambio climático | D14: Reacciones Alérgicas | E14: Desempleo | J14: Actividades de aventura acuática Lesiones físicas Falta de habilidad o entrenamiento Falta de Supervisión o Guías Expertos Riesgos Asociados con la Vida Silvestre Equipamiento Defectuoso o Inadecuado Comportamientos inadecuados en la actividad de aventura | L14: Contaminación intencional de producto | M14: Estado psicológico
B15: Pérdida de la biodiversidad | D15: Deshidratación por altas temperaturas de Calor | E15: ⁠Falta de apoyo e irrespeto a Grupos LGTB, indígenas / grupos étnicos | J15: Actividades de aventura terrestre Lesiones físicas Falta de habilidad o entrenamiento Falta de Supervisión o Guías Expertos Riesgos Asociados con la Vida Silvestre Equipamiento Defectuoso o Inadecuado Caída de rocas Esfuerzos físicos excesivos Terrenos Resbaladizos o Inestables Pérdida o Desorientación Desprendimientos de Rocas | L15: Generación residuos orgánicos | M15: Distractores o estímulos externos
B16: Término de prestación del servicio de manera anticipada con el gestor autorizado para la disposición final de los residuos | D16: Hipotermia | J16: Actividades de aventura áreas Condiciones Meteorológicas Adversas (Vientos Fuertes o Ráfagas, Tormentas y Rayos, Visibilidad Reducida, entre otros) Falta de habilidad o entrenamiento Falta de Supervisión o Guías Expertos Equipamiento Defectuoso o Inadecuado (Fallo del Paracaídas o Ala Delta, Defectos en el Equipo de Seguridad o Mantenimiento Inadecuado) Esfuerzos físicos excesivos Pérdida o Desorientación | L16: Perfil del personal que manipula alimentos | M16: Factor mecánico:
B17: Cierre de los rellenos sanitarios | L17: Perdida de la cadena de frío de los alimentos | M17: Mal estado del vehículo
B18: Terminación de permisos o concesiones ambientales (si aplica) | M18: Falta de mantenimientos preventivos
B19: Riesgo Gastronómico | M19: Falta de revisiones pre operacionales
B20: ⁠tormentas eléctricas , granizados, vientos , vendavales | M20: Desconocimiento del vehículo y sus dispositivos de seguridad
B21: Interrupciones en la cadena de suministro
B22: Disponibilidad y calidad de los alimentos | M22: Condiciones físicas de la vía como baches, rugosidad y derrumbes
B23: Contaminación Biológica (bacterias y virus hasta parásitos) | M23: Geometría y topografía de la vía: curvas pronunciadas
B24: Contaminación Química (que puede provenir de pesticidas, herbicidas, fertilizantes y productos químicos industriales) | M24: Señalización de la vía
B25: Fenómeno del niño | M25: Presencia de semovientes y obstáculos en la vía
B26: Fenómeno de la niña | M26: Características singulares de la vía: cruces, sectores poblados, estaciones de servicios o de mecánica básica
B27: Desbordes de caudales de ríos o quebradas | M27: Desconocimiento del territorio en el que se dan los desplazamientos
B28: Pérdidas agrícolas por sequías o inundaciones
B29: ⁠Incendios forestales
B30: Inundaciones
B31: Derrumbes
