Workbook

Sheet Taller
A1: LOGO DE LA ORGANIZACIÓN | C1: NOMBRE DE LA ORGANIZACIÓN | D1: TALLER DE LA COMPRENSIÓN DE LA ORGANIZACIÓN Y DE SU CONTEXTO | I1: CÓDIGO:
I2: VERSIÓN: 02
B4: Objetivo
B5: Realizar un análisis del contexto interno y externo, identificando los factores internos, externos negativos y positivos; que conlleven a la elaboración de un plan estratégico y de negocio del Prestador de Servicios Turísticos-PST.
B6: Definiciones
B7: Actividad de turismo de aventura: Actividad de aventura con fines turísticos que implica un grado de instrucción o liderazgo y un elemento de riesgo deliberadamente aceptado. (Fuente: NTC-ISO 21101) Alta dirección. Persona o grupo de personas que dirige y controla una organización al más alto nivel. (Fuente: NTC-ISO 21101) Estratégico. En un proceso regulable, conjunto de las reglas que buscan una decisión óptima en cada momento. (Fuente: Real Academia Española RAE) Factor negativo. Elemento o causa que actúan junto con otros, determinando si este es positivo. (Fuente: Real Academia Española RAE) Factor positivo. Elemento o causa que actúan junto con otros, determinando si este es negativo. (Fuente: Real Academia Española RAE) Objetivo. Resultado a lograr. (Fuente: NTC-ISO 21101) Plan. Modelo sistemático de una actuación pública o privada, que se elabora anticipadamente para dirigirla y encauzarla.(Fuente: Real Academia Española RAE) Política. Intenciones y dirección de una organización, como las expresa formalmente su alta dirección. (Fuente: NTC-ISO 21101) Política de seguridad. Política de una organización con respecto a su desempeño en materia de seguridad.(Fuente: NTC-ISO 21101) Proveedor de actividad de turismo de aventura: Individuo u organización que es responsable en general de todos los aspectos de la provisión de actividades de turismo de aventura. (Fuente: NTC-ISO 21101) Seguridad. Estado en el que el riesgo de daño (a las personas) o perjuicio se limita a un nivel aceptable. (Fuente: NTC-ISO 21101) Sistema de gestión. Conjunto de elementos de una organización que están interrelacionados o que interactúan para establecer políticas y objetivos y procesos para lograr estos objetivos. (Fuente: NTC-ISO 21101)
B9: Metodología del Taller:
B10: Los pasos a seguir son:
B12: Diligenciamiento de datos PST
B14: Por favor diligenciar lo siguientes datos de identificación del PST
B16: Fecha de diligenciamiento contexto | F16: 45504
B17: Nombre del PST | F17: TURISMO DE ADRENALINA
B18: Cargo del responsable del Plan Estratégico (PE) | F18: Pepito Pérez
B20: 1. Establecer el horizonte de tiempo del Plan Estratégico
B22: El horizonte de tiempo del Plan Estratégico es el periodo de tiempo inicio y fin del plan estratégico; para lo cual seleccione el inicio y fin, así:
B23: Año de inicio | E23: 2024 | F23: Año Fin | I23: 2027
B24: Se recomienda que el horizonte de tiempo del plan estratégico sea de 3 años.
B26: 2. Realizar el análisis de contexto interno y externo
B28: 2.1. Identificación de los factores internos
B30: Los factores internos son las debilidades y fortalezas que afectan al prestador de servicios turísticos (PST) internamente, las cuales identificamos como factores internos negativos y positivos.
B31: Los factores internos son:
B32: Planeación y Control Organizacional Son los factores relacionados con las metas, objetivos y estrategias, sistema de monitoreo, controles, actividades y planes establecidos de la organización. Cumplimiento de Requisitos (Normativos, Cliente) Son los factores relacionados con el cumplimiento de los requisitos legales, normativos y las expectativas del cliente en términos de calidad y seguridad. Gestión de seguridad Son los factores relacionados con la seguridad en las actividades de turismo de aventura que se desarrollen en la agencia, incluida la gestíon de riesgos. Gestión Comercial (Fuerza de Ventas) Son los factores relacionados con la planificación, dirección y control de las actividades comerciales, incluyendo la gestión de la fuerza de ventas para lograr los objetivos de ventas y marketing. | F32: Seguridad y Salud en el Trabajo Son los factores relacionados en implementación de políticas y prácticas para proteger la seguridad y la salud de los empleados, clientes, contratistas y partes interesadas en el entorno laboral. Talento Humano (Capacitación, Formación, Competencias del Personal) Son los factores relacionados con el desarrollo y gestión de las habilidades, conocimientos y competencias del personal a través de programas de capacitación y formación. Infraestructura Física Son los factores relacionados con instalaciones, activos y recursos físicos necesarios para llevar a cabo las operaciones de la organización, como herramientas, equipos y maquinaria. Infraestructura Tecnológica Son los factores relacionados con el conjunto de sistemas, software, hardware y redes que respaldan las operaciones y procesos tecnológicos de la organización.
B33: Retroalimentación de las Partes Interesadas Internas Son los factores relacionados con obtención de comentarios, opiniones y evaluaciones de los miembros internos de la organización para mejorar la comunicación y la toma de decisiones. | F33: Gestión Operacional Son los factores relacionados con la coordinación y supervisión de las operaciones diarias para garantizar la eficiencia, calidad, seguridad y cumplimiento de los objetivos organizacionales.
B35: Para la identificación iniciamos con los factores internos negativos y positivos, a través de los siguientes pasos:
B37: 2.1.1. Nos preguntamos cuales son nuestras factores internos negativos como prestador de servicios turísticos (PST) y la registramos en la hoja Contexto, así:
B39: (Columna No.): Es el código de identificación del factor interno negativo; para los factores internos negativos se asigna la letra D seguida del número que contiene la cantidad de factores internos que se tengan. Ejemplo: D1, D2, D3, D4 y así sucesivamente. (Columna Proceso): Se identifica el proceso donde se encuentra el factor interno negativo. (Columna Factores Internos Negativos): Seleccione el factor interno negativo identificado. (Columna Descripción): Describa el factor interno negativo. (Columna Prioridad Alta Dirección): Selección la prioridad que la Alta Dirección la cual se asignan acorde con la siguiente escala, así:
C41: Prioridad Alta Dirección | D41: Descripción
C42: Muy Alta | D42: Es significativo para el PST y requiere ejecución a corto plazo (menos de un año) dentro del Plan Estratégico
C43: Alta | D43: Es significativo para el PST y requiere ejecución a mediano (entre uno y dos años) plazo dentro del Plan Estratégico
C44: Media | D44: Es significativo para el PST y requiere ejecución a largo plazo (mas de 2 años y hasta 3 años) dentro del Plan Estratégico
C45: Baja | D45: No es significativo para PST y no requiere inclusión en el Plan Estratégico o se analizará en posteriores planes estratégicos
B48: No. | C48: Proceso | E48: Factores Internos Negativos | G48: Descripción | I48: Prioridad Alta Dirección
B49: D1 | C49: Gestión del Riesgo de turismo de aventura | E49: Planeación y control organizacional | G49: Mala planeación para la realización de las actividades de turismo de aventura. | I49: Muy Alta
B50: D2 | C50: Comunicación y consulta | E50: Retroalimentación de las partes interesadas internas | G50: No cuentan con un flujo de comunicación asertiva | I50: Baja
B55: 2.1.2. Nos preguntamos cuales son nuestras factores internos positivos como prestador de servicios turísticos (PST) y la registramos en la hoja Contexto, así:
B57: (Columna No.): Es el código de identificación del factor interno positivo; para los factores internos positivos se asigna la letra F seguida del número que contiene la cantidad de factores internos que se tengan. Ejemplo: F1, F2, F3, F4 y así sucesivamente. (Columna Proceso): Se identifica el proceso donde se encuentra el factor interno positivo. (Columna Factores Internos Positivos): Seleccione el factor interno positivo identificado. (Columna Descripción): Describa el factor interno positivo. (Columna Prioridad Alta Dirección): Selección la prioridad que la Alta Dirección la cual se asignan acorde con la siguiente escala, así:
C59: Prioridad Alta Dirección | D59: Descripción
C60: Muy Alta | D60: Es significativo para el PST y requiere ejecución a corto plazo (menos de un año) dentro del Plan Estratégico
C61: Alta | D61: Es significativo para el PST y requiere ejecución a mediano (entre uno y dos años) plazo dentro del Plan Estratégico
C62: Media | D62: Es significativo para el PST y requiere ejecución a largo plazo (mas de 2 años y hasta 3 años) dentro del Plan Estratégico
...

Sheet BSD
A1: LOGO DE LA ORGANIZACIÓN | B1: NOMBRE DE LA ORGANIZACIÓN | C1: BSD | F1: CÓDIGO:
F2: VERSIÓN:
A4: No. | B4: Nombre del proceso | E4: INTERNOS | H4: EXTERNOS | S4: No. | T4: FACTORES AMBIENTALES | V4: No. | W4: FACTORES ECONOMICOS | Y4: No. | Z4: FACTORES SOCIALES | AB4: No. | AC4: FACTORES TECNOLOGICOS | AE4: No. | AF4: FACTORES POLITICOS
A5: 1 | B5: Administrativo y Financiero | E5: Planeación y control organizacional | H5: Factores de seguridad | S5: 1 | T5: Fenómenos Climáticos | V5: 1 | W5: Disponibilidad presupuestal | Y5: 1 | Z5: Grupos marginados o población en condición de vulnerabilidad manifiesta, | AB5: 1 | AC5: Disponibilidad y Accesibilidad | AE5: 1 | AF5: Cambio de Gobierno y Políticas Públicas que definen planes, programas, proyectos y políticas Relaciones Internacionales
A6: 2 | B6: Gestión de seguridad | E6: Cumplimiento de requisitos (normativos, cliente) | H6: Factores políticos | S6: 2 | T6: Cambio Climático | V6: 2 | W6: Políticas económicas y monetarias. | Y6: 2 | Z6: Enfoque Diferencial, | AB6: 2 | AC6: Políticas sobre manejo de la información. | AE6: 2 | AF6: Cambio en legislación aplicable
A7: 3 | B7: Gestión Comercial | E7: Gestión de seguridad | H7: Factores legales | S7: 3 | T7: Entorno Ambiental | V7: 3 | W7: Dinámica de mercados. | Y7: 3 | Z7: Grupos sociales, étnicos y económicos. | AB7: 3 | AC7: Tecnología Emergente | AE7: 3
A8: 4 | B8: Reservas | E8: Gestión comercial (fuerza de ventas) | H8: Factores tecnológicos | S8: 4 | T8: Fenómenos Naturales o antrópicos no intencionales | V8: 4 | Y8: 4 | Z8: Políticas sobre Derechos Humanos | AB8: 4 | AC8: Nuevas tecnologías | AE8: 4
A9: 5 | B9: Gestión del riesgo de turismo de aventura | E9: Seguridad y Salud en el Trabajo | H9: Proveedores | S9: 5 | T9: Desarrollo y fortalecimiento en los territorios. | V9: 5 | Y9: 5 | AB9: 5 | AE9: 5
A10: 6 | B10: Comunicación y consulta | E10: Talento humano (capacitación, formación, competencias del personal) | H10: Clientes | S10: EXTERNOS | V10: EXTERNOS | Y10: EXTERNOS | AB10: EXTERNOS | AE10: EXTERNOS
A11: 7 | B11: Proceso 7 | E11: Infraestructura física | H11: Competencia
A12: 8 | B12: Proceso 8 | E12: Infraestructura tecnológica | H12: Mercado
A13: 9 | B13: Proceso 9 | E13: Retroalimentación de las partes interesadas internas | H13: Retroalimentación de las partes interesadas externas | S13: No. | T13: INFRAESTRUCTURA | V13: No. | W13: PERSONAL | Y13: No. | Z13: TECNOLOGIA | AB13: No. | AC13: PROCESOS | AE13: No. | AF13: FINANCIERO
A14: 10 | B14: Proceso 10 | E14: Gestión operacional | H14: Otros y cuáles | S14: 1 | T14: Infraestructura de operación | V14: 1 | W14: Competencia, formación y experiencia del talento humano | Y14: 1 | Z14: Integridad de Datos | AB14: 1 | AC14: Direccionamiento Estratégico | AE14: 1 | AF14: Disponibilidad recursos
A15: 11 | B15: Proceso 11 | E15: Otros y cuáles | H15: Otros y cuáles | S15: 2 | T15: Bienes muebles e inmuebles | V15: 2 | W15: Capacitación y formación del talento humano | Y15: 2 | Z15: Disponibilidad y seguridad de la Información | AB15: 2 | AC15: Estructura Funcional y Documental | AE15: 2 | AF15: Ingresos recibidos
A16: 12 | B16: Proceso 12 | E16: Otros y cuáles | H16: Otros y cuáles | S16: 3 | V16: 3 | W16: Factores relacionados con Seguridad y Salud en el Trabajo | Y16: 3 | Z16: Desarrollo y Mantenimiento Tecnológico. | AB16: 3 | AC16: Entradas, Planeación, Diseño, Ejecución, salidas, Proveedores, conocimiento y comunicación. | AE16: 3 | AF16: Costos y gastos asociados
A17: 13 | B17: Proceso 13 | E17: Otros y cuáles | H17: Otros y cuáles | S17: 4 | V17: 4 | W17: Talento humano | Y17: 4 | AB17: 4 | AE17: 4
A18: 14 | B18: Proceso 14 | E18: Otros y cuáles | H18: Otros y cuáles | S18: 5 | V18: 5 | Y18: 5 | AB18: 5 | AE18: 5
A19: 15 | B19: Todos los procesos | E19: Otros y cuáles | H19: Otros y cuáles | S19: INTERNOS | V19: INTERNOS | Y19: INTERNOS | AB19: INTERNOS | AE19: INTERNOS
A20: 16 | E20: Otros y cuáles | H20: Otros y cuáles
A21: 17 | E21: Otros y cuáles | H21: Otros y cuáles
A22: 18 | E22: Otros y cuáles | H22: Otros y cuáles
A23: 19 | N23: Frecuencia
A24: 20 | N24: Mensual
A25: 21 | N25: Bimensual
A26: 22 | N26: Bimestral
A27: 23 | N27: Trimestral
A28: 24 | N28: Cuatrimestral
A29: 25 | N29: Semestral
A30: 26 | N30: Anual
A31: 27
A32: 28
A33: 29
A34: 30
A35: 31
A36: 32
B41: Prioridad Alta Dirección | C41: Descripción | H41: Líneas Estratégicas | K41: Prioridad de actuación | L41: Descripción
B42: Muy Alta | C42: Es significativo para el PST y requiere ejecución a corto plazo (menos de un año) dentro del Plan Estratégico | H42: Seguridad | K42: Alta | L42: Capacidad ilimitada o lo que se requiera de recursos (Humano, financieros, físicos, tecnológicos entre otros)
B43: Alta | C43: Es significativo para el PST y requiere ejecución a mediano (entre uno y dos años) plazo dentro del Plan Estratégico | H43: Gestión de procesos | K43: Media | L43: Capacidad limitada o mínimo de recursos (Humano, financieros, físicos, tecnológicos entre otros)
B44: Media | C44: Es significativo para el PST y requiere ejecución a largo plazo (mas de 2 años y hasta 3 años) dentro del Plan Estratégico | H44: Crecimiento | K44: Baja | L44: No hay capacidad de recursos (Humano, financieros, físicos, tecnológicos entre otros)
B45: Baja | C45: No es significativo para PST y no requiere inclusión en el Plan Estratégico o se analizará en posteriores planes estratégicos | H45: Enfoque al cliente y/o partes interesadas
...

Sheet Contexto
A1: LOGO DE LA ORGANIZACIÓN | C1: NOMBRE DE LA ORGANIZACIÓN | D1: ANÁLISIS CONTEXTO INTERNO Y EXTERNO | Q1: CÓDIGO:
Q2: VERSIÓN: 02
A5: Fecha Actualización | C5: =Taller!$F$16 -> 45504 | E5: Nombre del PST | H5: =Taller!$F$17 -> TURISMO DE ADRENALINA | K5: Responsable | M5: =Taller!$F$18 -> Pepito Pérez
A7: CONTEXTO INTERNO | M7: CONTEXTO EXTERNO | Y7: ESTRATEGIAS
A8: No. | B8: Proceso | C8: Factores Internos Negativos | D8: Descripción | E8: Prioridad Alta Dirección | G8: No. | H8: Proceso | I8: Factores Internos Positivos | J8: Descripción | K8: Prioridad Alta Dirección | M8: No. | N8: Proceso | O8: Factores Externos Negativos | P8: Descripción | Q8: Prioridad Alta Dirección | S8: No. | T8: Proceso | U8: Factores Externos Positivos | V8: Descripción | W8: Prioridad Alta Dirección | Y8: No. | Z8: ESTRATEGIAS | AA8: No. | AB8: ESTRATEGIAS | AC8: No. | AD8: ESTRATEGIAS | AE8: No. | AF8: ESTRATEGIAS
A9: D1 | B9: Gestión del riesgo de turismo de aventura | C9: Planeación y control organizacional | D9: Mala planeación para la realización de las actividades de turismo de aventura. | E9: Muy Alta | G9: F1 | H9: Administrativo y Financiero | I9: Talento humano (capacitación, formación, competencias del personal) | J9: Personal capacitado excelente para atención al cliente | K9: Alta | M9: A1 | N9: Gestión del riesgo de turismo de aventura | O9: Factores de seguridad | P9: Inseguridad y terrorismo en el país | Q9: Baja | S9: O1 | T9: Administrativo y Financiero | U9: Factores legales | V9: Cambios normativos y legales a nivel turismo y subsidios favorables | W9: Alta | Y9: E1 | Z9: Certificaciones | AA9: E2 | AB9: Estrategia | AC9: E3 | AD9: Estrategia | AE9: E4 | AF9: Estrategia
A10: D2 | B10: Comunicación y consulta | C10: Retroalimentación de las partes interesadas internas | D10: No cuentan con canales de comunicación asertiva. | E10: Baja | G10: F2 | H10: Gestión Comercial | I10: Gestión comercial (fuerza de ventas) | J10: Experiencia en turismo de aventura | K10: Muy Alta | M10: A2 | N10: Comunicación y consulta | O10: Factores tecnológicos | P10: Cambios acelerados en la tecnología y herramientas de comunicación para informar a los clientes sobre el servicio | Q10: Media | S10: O2 | T10: Gestión Comercial | U10: Mercado | V10: Plan de Nacional de Desarrollo enfoca el turismo armonía con la vida e incluyente con las comunidades | W10: Baja | Y10: E5 | Z10: Estrategia | AA10: E6 | AB10: Estrategia | AC10: E7 | AD10: Estrategia | AE10: E8 | AF10: Estrategia
A11: D3 | G11: F3 | M11: A3 | S11: O3 | Y11: E9 | Z11: Estrategia | AA11: E10 | AB11: Estrategia | AC11: E11 | AD11: Estrategia | AE11: E12 | AF11: Estrategia
A12: D4 | G12: F4 | M12: A4 | S12: O4 | Y12: E13 | Z12: Estrategia | AA12: E14 | AB12: Estrategia | AC12: E15 | AD12: Estrategia | AE12: E16 | AF12: Estrategia
A13: D5 | G13: F5 | M13: A5 | S13: O5 | Y13: E17 | Z13: Estrategia | AA13: E18 | AB13: Estrategia | AC13: E19 | AD13: Estrategia | AE13: E20 | AF13: Estrategia
A14: D6 | G14: F6 | M14: A6 | S14: O6
A15: D7 | G15: F7 | M15: A7 | S15: O7
A16: D8 | G16: F8 | M16: A8 | S16: O8
A17: D9 | G17: F9 | M17: A9 | S17: O9
A18: D10 | G18: F10 | M18: A10 | S18: O10
A21: Nota: Es importante establecer la prioridad de la Alta Dirección, con el fin de dar prioridad para al implementación del Plan Estratégico del PST. Los factores internos y externos positivos y los factores internos y externos negativos se pueden convertir en Oportunidades y Riesgos; los cuales se conectan con el mapa de riesgos y oportunidades en cual se seleccionan la fuente de análisis de contexto.

Sheet Matriz cruzada
A1: LOGO DE LA ORGANZACIÓN | C1: NOMBRE DE LA ORGANIZACIÓN | D1: MATRIZ CRUZADA | J1: CÓDIGO:
J2: VERSIÓN:02
A4: No. | B4: Proceso | C4: Tipo de Factor | D4: Factor | E4: Descripción | F4: Prioridad Alta Dirección | G4: Cruce | H4: Línea Estratégica | I4: Objetivo | J4: Estrategia | K4: Prioridad de recursos
A5: D1 | B5: =IF(VLOOKUP($A5,Contexto!$A$8:$E$18,2,0)=0,"",VLOOKUP($A5,Contexto!$A$8:$E$18,2,0)) -> Gestión del riesgo de turismo de aventura | C5: =IF($B5="","",VLOOKUP($A5,BSD!$A$48:$B$87,2,0)) -> Factores Internos Negativos | D5: =IF(VLOOKUP($A5,Contexto!$A$8:$E$18,3,0)=0,"",VLOOKUP($A5,Contexto!$A$8:$E$18,3,0)) -> Planeación y control organizacional | E5: =IF(VLOOKUP($A5,Contexto!$A$8:$E$18,4,0)=0,"",VLOOKUP($A5,Contexto!$A$8:$E$18,4,0)) -> Mala planeación para la realización de las actividades de turismo de aventura. | F5: =IF(VLOOKUP($A5,Contexto!$A$8:$E$18,5,0)=0,"",VLOOKUP($A5,Contexto!$A$8:$E$18,5,0)) -> Muy Alta | G5: D1, F1, F2 | H5: Gestión de procesos | I5: Mejorar la gestión de los procesos, aumentando la seguridad en nuestras operaciones al 95%. | J5: Documentar los procesos del sistema de gestión de turismo de aventura, para garantizar una buena planificación y gestión de las actividades de la agencia. | K5: Alta
A6: D2 | B6: =IF(VLOOKUP($A6,Contexto!$A$8:$E$18,2,0)=0,"",VLOOKUP($A6,Contexto!$A$8:$E$18,2,0)) -> Comunicación y consulta | C6: =IF($B6="","",VLOOKUP($A6,BSD!$A$48:$B$87,2,0)) -> Factores Internos Negativos | D6: =IF(VLOOKUP($A6,Contexto!$A$8:$E$18,3,0)=0,"",VLOOKUP($A6,Contexto!$A$8:$E$18,3,0)) -> Retroalimentación de las partes interesadas internas | E6: =IF(VLOOKUP($A6,Contexto!$A$8:$E$18,4,0)=0,"",VLOOKUP($A6,Contexto!$A$8:$E$18,4,0)) -> No cuentan con canales de comunicación asertiva. | F6: =IF(VLOOKUP($A6,Contexto!$A$8:$E$18,5,0)=0,"",VLOOKUP($A6,Contexto!$A$8:$E$18,5,0)) -> Baja | G6: A2 | H6: Gestión de procesos | I6: Documentar un proceso de comunicación y consulta con el personal y otras personas que participan en la prestación de actividades de turismo de aventura. | J6: Elaborar e implementar los documentos de la organización | K6: Alta
A7: D3 | B7: =IF(VLOOKUP($A7,Contexto!$A$8:$E$18,2,0)=0,"",VLOOKUP($A7,Contexto!$A$8:$E$18,2,0)) | C7: =IF($B7="","",VLOOKUP($A7,BSD!$A$48:$B$87,2,0)) | D7: =IF(VLOOKUP($A7,Contexto!$A$8:$E$18,3,0)=0,"",VLOOKUP($A7,Contexto!$A$8:$E$18,3,0)) | E7: =IF(VLOOKUP($A7,Contexto!$A$8:$E$18,4,0)=0,"",VLOOKUP($A7,Contexto!$A$8:$E$18,4,0)) | F7: =IF(VLOOKUP($A7,Contexto!$A$8:$E$18,5,0)=0,"",VLOOKUP($A7,Contexto!$A$8:$E$18,5,0))
A8: D4 | B8: =IF(VLOOKUP($A8,Contexto!$A$8:$E$18,2,0)=0,"",VLOOKUP($A8,Contexto!$A$8:$E$18,2,0)) | C8: =IF($B8="","",VLOOKUP($A8,BSD!$A$48:$B$87,2,0)) | D8: =IF(VLOOKUP($A8,Contexto!$A$8:$E$18,3,0)=0,"",VLOOKUP($A8,Contexto!$A$8:$E$18,3,0)) | E8: =IF(VLOOKUP($A8,Contexto!$A$8:$E$18,4,0)=0,"",VLOOKUP($A8,Contexto!$A$8:$E$18,4,0)) | F8: =IF(VLOOKUP($A8,Contexto!$A$8:$E$18,5,0)=0,"",VLOOKUP($A8,Contexto!$A$8:$E$18,5,0))
A9: D5 | B9: =IF(VLOOKUP($A9,Contexto!$A$8:$E$18,2,0)=0,"",VLOOKUP($A9,Contexto!$A$8:$E$18,2,0)) | C9: =IF($B9="","",VLOOKUP($A9,BSD!$A$48:$B$87,2,0)) | D9: =IF(VLOOKUP($A9,Contexto!$A$8:$E$18,3,0)=0,"",VLOOKUP($A9,Contexto!$A$8:$E$18,3,0)) | E9: =IF(VLOOKUP($A9,Contexto!$A$8:$E$18,4,0)=0,"",VLOOKUP($A9,Contexto!$A$8:$E$18,4,0)) | F9: =IF(VLOOKUP($A9,Contexto!$A$8:$E$18,5,0)=0,"",VLOOKUP($A9,Contexto!$A$8:$E$18,5,0))
A10: D6 | B10: =IF(VLOOKUP($A10,Contexto!$A$8:$E$18,2,0)=0,"",VLOOKUP($A10,Contexto!$A$8:$E$18,2,0)) | C10: =IF($B10="","",VLOOKUP($A10,BSD!$A$48:$B$87,2,0)) | D10: =IF(VLOOKUP($A10,Contexto!$A$8:$E$18,3,0)=0,"",VLOOKUP($A10,Contexto!$A$8:$E$18,3,0)) | E10: =IF(VLOOKUP($A10,Contexto!$A$8:$E$18,4,0)=0,"",VLOOKUP($A10,Contexto!$A$8:$E$18,4,0)) | F10: =IF(VLOOKUP($A10,Contexto!$A$8:$E$18,5,0)=0,"",VLOOKUP($A10,Contexto!$A$8:$E$18,5,0))
A11: D7 | B11: =IF(VLOOKUP($A11,Contexto!$A$8:$E$18,2,0)=0,"",VLOOKUP($A11,Contexto!$A$8:$E$18,2,0)) | C11: =IF($B11="","",VLOOKUP($A11,BSD!$A$48:$B$87,2,0)) | D11: =IF(VLOOKUP($A11,Contexto!$A$8:$E$18,3,0)=0,"",VLOOKUP($A11,Contexto!$A$8:$E$18,3,0)) | E11: =IF(VLOOKUP($A11,Contexto!$A$8:$E$18,4,0)=0,"",VLOOKUP($A11,Contexto!$A$8:$E$18,4,0)) | F11: =IF(VLOOKUP($A11,Contexto!$A$8:$E$18,5,0)=0,"",VLOOKUP($A11,Contexto!$A$8:$E$18,5,0))
A12: D8 | B12: =IF(VLOOKUP($A12,Contexto!$A$8:$E$18,2,0)=0,"",VLOOKUP($A12,Contexto!$A$8:$E$18,2,0)) | C12: =IF($B12="","",VLOOKUP($A12,BSD!$A$48:$B$87,2,0)) | D12: =IF(VLOOKUP($A12,Contexto!$A$8:$E$18,3,0)=0,"",VLOOKUP($A12,Contexto!$A$8:$E$18,3,0)) | E12: =IF(VLOOKUP($A12,Contexto!$A$8:$E$18,4,0)=0,"",VLOOKUP($A12,Contexto!$A$8:$E$18,4,0)) | F12: =IF(VLOOKUP($A12,Contexto!$A$8:$E$18,5,0)=0,"",VLOOKUP($A12,Contexto!$A$8:$E$18,5,0))
A13: D9 | B13: =IF(VLOOKUP($A13,Contexto!$A$8:$E$18,2,0)=0,"",VLOOKUP($A13,Contexto!$A$8:$E$18,2,0)) | C13: =IF($B13="","",VLOOKUP($A13,BSD!$A$48:$B$87,2,0)) | D13: =IF(VLOOKUP($A13,Contexto!$A$8:$E$18,3,0)=0,"",VLOOKUP($A13,Contexto!$A$8:$E$18,3,0)) | E13: =IF(VLOOKUP($A13,Contexto!$A$8:$E$18,4,0)=0,"",VLOOKUP($A13,Contexto!$A$8:$E$18,4,0)) | F13: =IF(VLOOKUP($A13,Contexto!$A$8:$E$18,5,0)=0,"",VLOOKUP($A13,Contexto!$A$8:$E$18,5,0))
A14: D10 | B14: =IF(VLOOKUP($A14,Contexto!$A$8:$E$18,2,0)=0,"",VLOOKUP($A14,Contexto!$A$8:$E$18,2,0)) | C14: =IF($B14="","",VLOOKUP($A14,BSD!$A$48:$B$87,2,0)) | D14: =IF(VLOOKUP($A14,Contexto!$A$8:$E$18,3,0)=0,"",VLOOKUP($A14,Contexto!$A$8:$E$18,3,0)) | E14: =IF(VLOOKUP($A14,Contexto!$A$8:$E$18,4,0)=0,"",VLOOKUP($A14,Contexto!$A$8:$E$18,4,0)) | F14: =IF(VLOOKUP($A14,Contexto!$A$8:$E$18,5,0)=0,"",VLOOKUP($A14,Contexto!$A$8:$E$18,5,0))
A15: F1 | B15: =IF(VLOOKUP($A15,Contexto!$G$8:$K$18,2,0)=0,"",VLOOKUP($A15,Contexto!$G$8:$K$18,2,0)) -> Administrativo y Financiero | C15: =IF($B15="","",VLOOKUP($A15,BSD!$A$48:$B$87,2,0)) -> Factores Internos Positivos | D15: =IF(VLOOKUP($A15,Contexto!$G$8:$K$18,3,0)=0,"",VLOOKUP($A15,Contexto!$G$8:$K$18,3,0)) -> Talento humano (capacitación, formación, competencias del personal) | E15: =IF(VLOOKUP($A15,Contexto!$G$8:$K$18,4,0)=0,"",VLOOKUP($A15,Contexto!$G$8:$K$18,4,0)) -> Personal capacitado excelente para atención al cliente | F15: =IF(VLOOKUP($A15,Contexto!$G$8:$K$18,5,0)=0,"",VLOOKUP($A15,Contexto!$G$8:$K$18,5,0)) -> Alta | G15: D1, F1, F2 | H15: Crecimiento | I15: Aumentar la ventas en 10% con respecto al año anterior | J15: Fortalecer la gestión comercial a través de la consecución de los recursos para las actividades de turismo y condiciones de talento humano. | K15: Alta
A16: F2 | B16: =IF(VLOOKUP($A16,Contexto!$G$8:$K$18,2,0)=0,"",VLOOKUP($A16,Contexto!$G$8:$K$18,2,0)) -> Gestión Comercial | C16: =IF($B16="","",VLOOKUP($A16,BSD!$A$48:$B$87,2,0)) -> Factores Internos Positivos | D16: =IF(VLOOKUP($A16,Contexto!$G$8:$K$18,3,0)=0,"",VLOOKUP($A16,Contexto!$G$8:$K$18,3,0)) -> Gestión comercial (fuerza de ventas) | E16: =IF(VLOOKUP($A16,Contexto!$G$8:$K$18,4,0)=0,"",VLOOKUP($A16,Contexto!$G$8:$K$18,4,0)) -> Experiencia en turismo de aventura | F16: =IF(VLOOKUP($A16,Contexto!$G$8:$K$18,5,0)=0,"",VLOOKUP($A16,Contexto!$G$8:$K$18,5,0)) -> Muy Alta | G16: D1, F1, F2 | H16: Crecimiento | I16: Aumentar la ventas en 10% con respecto al año anterior | J16: Fortalecer la gestión comercial en turismo a través de la consecución de los recursos para las actividades de turismo y condiciones de talento humano. | K16: Alta
A17: F3 | B17: =IF(VLOOKUP($A17,Contexto!$G$8:$K$18,2,0)=0,"",VLOOKUP($A17,Contexto!$G$8:$K$18,2,0)) | C17: =IF($B17="","",VLOOKUP($A17,BSD!$A$48:$B$87,2,0)) | D17: =IF(VLOOKUP($A17,Contexto!$G$8:$K$18,3,0)=0,"",VLOOKUP($A17,Contexto!$G$8:$K$18,3,0)) | E17: =IF(VLOOKUP($A17,Contexto!$G$8:$K$18,4,0)=0,"",VLOOKUP($A17,Contexto!$G$8:$K$18,4,0)) | F17: =IF(VLOOKUP($A17,Contexto!$G$8:$K$18,5,0)=0,"",VLOOKUP($A17,Contexto!$G$8:$K$18,5,0))
A18: F4 | B18: =IF(VLOOKUP($A18,Contexto!$G$8:$K$18,2,0)=0,"",VLOOKUP($A18,Contexto!$G$8:$K$18,2,0)) | C18: =IF($B18="","",VLOOKUP($A18,BSD!$A$48:$B$87,2,0)) | D18: =IF(VLOOKUP($A18,Contexto!$G$8:$K$18,3,0)=0,"",VLOOKUP($A18,Contexto!$G$8:$K$18,3,0)) | E18: =IF(VLOOKUP($A18,Contexto!$G$8:$K$18,4,0)=0,"",VLOOKUP($A18,Contexto!$G$8:$K$18,4,0)) | F18: =IF(VLOOKUP($A18,Contexto!$G$8:$K$18,5,0)=0,"",VLOOKUP($A18,Contexto!$G$8:$K$18,5,0))
A19: F5 | B19: =IF(VLOOKUP($A19,Contexto!$G$8:$K$18,2,0)=0,"",VLOOKUP($A19,Contexto!$G$8:$K$18,2,0)) | C19: =IF($B19="","",VLOOKUP($A19,BSD!$A$48:$B$87,2,0)) | D19: =IF(VLOOKUP($A19,Contexto!$G$8:$K$18,3,0)=0,"",VLOOKUP($A19,Contexto!$G$8:$K$18,3,0)) | E19: =IF(VLOOKUP($A19,Contexto!$G$8:$K$18,4,0)=0,"",VLOOKUP($A19,Contexto!$G$8:$K$18,4,0)) | F19: =IF(VLOOKUP($A19,Contexto!$G$8:$K$18,5,0)=0,"",VLOOKUP($A19,Contexto!$G$8:$K$18,5,0))
A20: F6 | B20: =IF(VLOOKUP($A20,Contexto!$G$8:$K$18,2,0)=0,"",VLOOKUP($A20,Contexto!$G$8:$K$18,2,0)) | C20: =IF($B20="","",VLOOKUP($A20,BSD!$A$48:$B$87,2,0)) | D20: =IF(VLOOKUP($A20,Contexto!$G$8:$K$18,3,0)=0,"",VLOOKUP($A20,Contexto!$G$8:$K$18,3,0)) | E20: =IF(VLOOKUP($A20,Contexto!$G$8:$K$18,4,0)=0,"",VLOOKUP($A20,Contexto!$G$8:$K$18,4,0)) | F20: =IF(VLOOKUP($A20,Contexto!$G$8:$K$18,5,0)=0,"",VLOOKUP($A20,Contexto!$G$8:$K$18,5,0))
A21: F7 | B21: =IF(VLOOKUP($A21,Contexto!$G$8:$K$18,2,0)=0,"",VLOOKUP($A21,Contexto!$G$8:$K$18,2,0)) | C21: =IF($B21="","",VLOOKUP($A21,BSD!$A$48:$B$87,2,0)) | D21: =IF(VLOOKUP($A21,Contexto!$G$8:$K$18,3,0)=0,"",VLOOKUP($A21,Contexto!$G$8:$K$18,3,0)) | E21: =IF(VLOOKUP($A21,Contexto!$G$8:$K$18,4,0)=0,"",VLOOKUP($A21,Contexto!$G$8:$K$18,4,0)) | F21: =IF(VLOOKUP($A21,Contexto!$G$8:$K$18,5,0)=0,"",VLOOKUP($A21,Contexto!$G$8:$K$18,5,0))
A22: F8 | B22: =IF(VLOOKUP($A22,Contexto!$G$8:$K$18,2,0)=0,"",VLOOKUP($A22,Contexto!$G$8:$K$18,2,0)) | C22: =IF($B22="","",VLOOKUP($A22,BSD!$A$48:$B$87,2,0)) | D22: =IF(VLOOKUP($A22,Contexto!$G$8:$K$18,3,0)=0,"",VLOOKUP($A22,Contexto!$G$8:$K$18,3,0)) | E22: =IF(VLOOKUP($A22,Contexto!$G$8:$K$18,4,0)=0,"",VLOOKUP($A22,Contexto!$G$8:$K$18,4,0)) | F22: =IF(VLOOKUP($A22,Contexto!$G$8:$K$18,5,0)=0,"",VLOOKUP($A22,Contexto!$G$8:$K$18,5,0))
A23: F9 | B23: =IF(VLOOKUP($A23,Contexto!$G$8:$K$18,2,0)=0,"",VLOOKUP($A23,Contexto!$G$8:$K$18,2,0)) | C23: =IF($B23="","",VLOOKUP($A23,BSD!$A$48:$B$87,2,0)) | D23: =IF(VLOOKUP($A23,Contexto!$G$8:$K$18,3,0)=0,"",VLOOKUP($A23,Contexto!$G$8:$K$18,3,0)) | E23: =IF(VLOOKUP($A23,Contexto!$G$8:$K$18,4,0)=0,"",VLOOKUP($A23,Contexto!$G$8:$K$18,4,0)) | F23: =IF(VLOOKUP($A23,Contexto!$G$8:$K$18,5,0)=0,"",VLOOKUP($A23,Contexto!$G$8:$K$18,5,0))
A24: F10 | B24: =IF(VLOOKUP($A24,Contexto!$G$8:$K$18,2,0)=0,"",VLOOKUP($A24,Contexto!$G$8:$K$18,2,0)) | C24: =IF($B24="","",VLOOKUP($A24,BSD!$A$48:$B$87,2,0)) | D24: =IF(VLOOKUP($A24,Contexto!$G$8:$K$18,3,0)=0,"",VLOOKUP($A24,Contexto!$G$8:$K$18,3,0)) | E24: =IF(VLOOKUP($A24,Contexto!$G$8:$K$18,4,0)=0,"",VLOOKUP($A24,Contexto!$G$8:$K$18,4,0)) | F24: =IF(VLOOKUP($A24,Contexto!$G$8:$K$18,5,0)=0,"",VLOOKUP($A24,Contexto!$G$8:$K$18,5,0))
A25: A1 | B25: =IF(VLOOKUP($A25,Contexto!$M$8:$Q$18,2,0)=0,"",VLOOKUP($A25,Contexto!$M$8:$Q$18,2,0)) -> Gestión del riesgo de turismo de aventura | C25: =IF($B25="","",VLOOKUP($A25,BSD!$A$48:$B$87,2,0)) -> Factores Externos Negativos | D25: =IF(VLOOKUP($A25,Contexto!$M$8:$Q$18,3,0)=0,"",VLOOKUP($A25,Contexto!$M$8:$Q$18,3,0)) -> Factores de seguridad | E25: =IF(VLOOKUP($A25,Contexto!$M$8:$Q$18,4,0)=0,"",VLOOKUP($A25,Contexto!$M$8:$Q$18,4,0)) -> Inseguridad y terrorismo en el país | F25: =IF(VLOOKUP($A25,Contexto!$M$8:$Q$18,5,0)=0,"",VLOOKUP($A25,Contexto!$M$8:$Q$18,5,0)) -> Baja | G25: A1,O2 | H25: Crecimiento | I25: Aumentar la ventas en 10% con respecto al año anterior | J25: Desarrollar o fortalecer los canales de venta de la organización, teniendo en cuenta el contexto de seguridad y planeación del país | K25: Alta
A26: A2 | B26: =IF(VLOOKUP($A26,Contexto!$M$8:$Q$18,2,0)=0,"",VLOOKUP($A26,Contexto!$M$8:$Q$18,2,0)) -> Comunicación y consulta | C26: =IF($B26="","",VLOOKUP($A26,BSD!$A$48:$B$87,2,0)) -> Factores Externos Negativos | D26: =IF(VLOOKUP($A26,Contexto!$M$8:$Q$18,3,0)=0,"",VLOOKUP($A26,Contexto!$M$8:$Q$18,3,0)) -> Factores tecnológicos | E26: =IF(VLOOKUP($A26,Contexto!$M$8:$Q$18,4,0)=0,"",VLOOKUP($A26,Contexto!$M$8:$Q$18,4,0)) -> Cambios acelerados en la tecnología y herramientas de comunicación para informar a los clientes sobre el servicio | F26: =IF(VLOOKUP($A26,Contexto!$M$8:$Q$18,5,0)=0,"",VLOOKUP($A26,Contexto!$M$8:$Q$18,5,0)) -> Media | G26: D2 | H26: Crecimiento | I26: Implementar un plan de TI que contenga innovación durante el próximo año. | J26: Innovar y transformar nuestros servicios por medio del uso de plataformas de tecnología y canales digitales para ofertar los servicios. | K26: Alta
A27: A3 | B27: =IF(VLOOKUP($A27,Contexto!$M$8:$Q$18,2,0)=0,"",VLOOKUP($A27,Contexto!$M$8:$Q$18,2,0)) | C27: =IF($B27="","",VLOOKUP($A27,BSD!$A$48:$B$87,2,0)) | D27: =IF(VLOOKUP($A27,Contexto!$M$8:$Q$18,3,0)=0,"",VLOOKUP($A27,Contexto!$M$8:$Q$18,3,0)) | E27: =IF(VLOOKUP($A27,Contexto!$M$8:$Q$18,4,0)=0,"",VLOOKUP($A27,Contexto!$M$8:$Q$18,4,0)) | F27: =IF(VLOOKUP($A27,Contexto!$M$8:$Q$18,5,0)=0,"",VLOOKUP($A27,Contexto!$M$8:$Q$18,5,0))
A28: A4 | B28: =IF(VLOOKUP($A28,Contexto!$M$8:$Q$18,2,0)=0,"",VLOOKUP($A28,Contexto!$M$8:$Q$18,2,0)) | C28: =IF($B28="","",VLOOKUP($A28,BSD!$A$48:$B$87,2,0)) | D28: =IF(VLOOKUP($A28,Contexto!$M$8:$Q$18,3,0)=0,"",VLOOKUP($A28,Contexto!$M$8:$Q$18,3,0)) | E28: =IF(VLOOKUP($A28,Contexto!$M$8:$Q$18,4,0)=0,"",VLOOKUP($A28,Contexto!$M$8:$Q$18,4,0)) | F28: =IF(VLOOKUP($A28,Contexto!$M$8:$Q$18,5,0)=0,"",VLOOKUP($A28,Contexto!$M$8:$Q$18,5,0))
A29: A5 | B29: =IF(VLOOKUP($A29,Contexto!$M$8:$Q$18,2,0)=0,"",VLOOKUP($A29,Contexto!$M$8:$Q$18,2,0)) | C29: =IF($B29="","",VLOOKUP($A29,BSD!$A$48:$B$87,2,0)) | D29: =IF(VLOOKUP($A29,Contexto!$M$8:$Q$18,3,0)=0,"",VLOOKUP($A29,Contexto!$M$8:$Q$18,3,0)) | E29: =IF(VLOOKUP($A29,Contexto!$M$8:$Q$18,4,0)=0,"",VLOOKUP($A29,Contexto!$M$8:$Q$18,4,0)) | F29: =IF(VLOOKUP($A29,Contexto!$M$8:$Q$18,5,0)=0,"",VLOOKUP($A29,Contexto!$M$8:$Q$18,5,0))
A30: A6 | B30: =IF(VLOOKUP($A30,Contexto!$M$8:$Q$18,2,0)=0,"",VLOOKUP($A30,Contexto!$M$8:$Q$18,2,0)) | C30: =IF($B30="","",VLOOKUP($A30,BSD!$A$48:$B$87,2,0)) | D30: =IF(VLOOKUP($A30,Contexto!$M$8:$Q$18,3,0)=0,"",VLOOKUP($A30,Contexto!$M$8:$Q$18,3,0)) | E30: =IF(VLOOKUP($A30,Contexto!$M$8:$Q$18,4,0)=0,"",VLOOKUP($A30,Contexto!$M$8:$Q$18,4,0)) | F30: =IF(VLOOKUP($A30,Contexto!$M$8:$Q$18,5,0)=0,"",VLOOKUP($A30,Contexto!$M$8:$Q$18,5,0))
A31: A7 | B31: =IF(VLOOKUP($A31,Contexto!$M$8:$Q$18,2,0)=0,"",VLOOKUP($A31,Contexto!$M$8:$Q$18,2,0)) | C31: =IF($B31="","",VLOOKUP($A31,BSD!$A$48:$B$87,2,0)) | D31: =IF(VLOOKUP($A31,Contexto!$M$8:$Q$18,3,0)=0,"",VLOOKUP($A31,Contexto!$M$8:$Q$18,3,0)) | E31: =IF(VLOOKUP($A31,Contexto!$M$8:$Q$18,4,0)=0,"",VLOOKUP($A31,Contexto!$M$8:$Q$18,4,0)) | F31: =IF(VLOOKUP($A31,Contexto!$M$8:$Q$18,5,0)=0,"",VLOOKUP($A31,Contexto!$M$8:$Q$18,5,0))
A32: A8 | B32: =IF(VLOOKUP($A32,Contexto!$M$8:$Q$18,2,0)=0,"",VLOOKUP($A32,Contexto!$M$8:$Q$18,2,0)) | C32: =IF($B32="","",VLOOKUP($A32,BSD!$A$48:$B$87,2,0)) | D32: =IF(VLOOKUP($A32,Contexto!$M$8:$Q$18,3,0)=0,"",VLOOKUP($A32,Contexto!$M$8:$Q$18,3,0)) | E32: =IF(VLOOKUP($A32,Contexto!$M$8:$Q$18,4,0)=0,"",VLOOKUP($A32,Contexto!$M$8:$Q$18,4,0)) | F32: =IF(VLOOKUP($A32,Contexto!$M$8:$Q$18,5,0)=0,"",VLOOKUP($A32,Contexto!$M$8:$Q$18,5,0))
A33: A9 | B33: =IF(VLOOKUP($A33,Contexto!$M$8:$Q$18,2,0)=0,"",VLOOKUP($A33,Contexto!$M$8:$Q$18,2,0)) | C33: =IF($B33="","",VLOOKUP($A33,BSD!$A$48:$B$87,2,0)) | D33: =IF(VLOOKUP($A33,Contexto!$M$8:$Q$18,3,0)=0,"",VLOOKUP($A33,Contexto!$M$8:$Q$18,3,0)) | E33: =IF(VLOOKUP($A33,Contexto!$M$8:$Q$18,4,0)=0,"",VLOOKUP($A33,Contexto!$M$8:$Q$18,4,0)) | F33: =IF(VLOOKUP($A33,Contexto!$M$8:$Q$18,5,0)=0,"",VLOOKUP($A33,Contexto!$M$8:$Q$18,5,0))
A34: A10 | B34: =IF(VLOOKUP($A34,Contexto!$M$8:$Q$18,2,0)=0,"",VLOOKUP($A34,Contexto!$M$8:$Q$18,2,0)) | C34: =IF($B34="","",VLOOKUP($A34,BSD!$A$48:$B$87,2,0)) | D34: =IF(VLOOKUP($A34,Contexto!$M$8:$Q$18,3,0)=0,"",VLOOKUP($A34,Contexto!$M$8:$Q$18,3,0)) | E34: =IF(VLOOKUP($A34,Contexto!$M$8:$Q$18,4,0)=0,"",VLOOKUP($A34,Contexto!$M$8:$Q$18,4,0)) | F34: =IF(VLOOKUP($A34,Contexto!$M$8:$Q$18,5,0)=0,"",VLOOKUP($A34,Contexto!$M$8:$Q$18,5,0))
A35: O1 | B35: =IF(VLOOKUP($A35,Contexto!$S$8:$W$18,2,0)=0,"",VLOOKUP($A35,Contexto!$S$8:$W$18,2,0)) -> Administrativo y Financiero | C35: =IF($B35="","",VLOOKUP($A35,BSD!$A$48:$B$87,2,0)) -> Factores Externos Positivos | D35: =IF(VLOOKUP($A35,Contexto!$S$8:$W$18,3,0)=0,"",VLOOKUP($A35,Contexto!$S$8:$W$18,3,0)) -> Factores legales | E35: =IF(VLOOKUP($A35,Contexto!$S$8:$W$18,4,0)=0,"",VLOOKUP($A35,Contexto!$S$8:$W$18,4,0)) -> Cambios normativos y legales a nivel turismo y subsidios favorables | F35: =IF(VLOOKUP($A35,Contexto!$S$8:$W$18,5,0)=0,"",VLOOKUP($A35,Contexto!$S$8:$W$18,5,0)) -> Alta | G35: F2 | H35: Crecimiento | I35: Aumentar la ventas en 10% con respecto al año anterior. | J35: Diseñar un nuevo servicio enfocado en los temas según cambios normativos. | K35: Media
A36: O2 | B36: =IF(VLOOKUP($A36,Contexto!$S$8:$W$18,2,0)=0,"",VLOOKUP($A36,Contexto!$S$8:$W$18,2,0)) -> Gestión Comercial | C36: =IF($B36="","",VLOOKUP($A36,BSD!$A$48:$B$87,2,0)) -> Factores Externos Positivos | D36: =IF(VLOOKUP($A36,Contexto!$S$8:$W$18,3,0)=0,"",VLOOKUP($A36,Contexto!$S$8:$W$18,3,0)) -> Mercado | E36: =IF(VLOOKUP($A36,Contexto!$S$8:$W$18,4,0)=0,"",VLOOKUP($A36,Contexto!$S$8:$W$18,4,0)) -> Plan de Nacional de Desarrollo enfoca el turismo armonía con la vida e incluyente con las comunidades | F36: =IF(VLOOKUP($A36,Contexto!$S$8:$W$18,5,0)=0,"",VLOOKUP($A36,Contexto!$S$8:$W$18,5,0)) -> Baja | G36: F1 | H36: Crecimiento | I36: Aumentar la ventas en 10% con respecto al año anterior | J36: Desarrollar o fortalecer los canales de venta de la organización, teniendo en cuenta el plan nacional de desarrollo. | K36: Alta
A37: O3 | B37: =IF(VLOOKUP($A37,Contexto!$S$8:$W$18,2,0)=0,"",VLOOKUP($A37,Contexto!$S$8:$W$18,2,0)) | C37: =IF($B37="","",VLOOKUP($A37,BSD!$A$48:$B$87,2,0)) | D37: =IF(VLOOKUP($A37,Contexto!$S$8:$W$18,3,0)=0,"",VLOOKUP($A37,Contexto!$S$8:$W$18,3,0)) | E37: =IF(VLOOKUP($A37,Contexto!$S$8:$W$18,4,0)=0,"",VLOOKUP($A37,Contexto!$S$8:$W$18,4,0)) | F37: =IF(VLOOKUP($A37,Contexto!$S$8:$W$18,5,0)=0,"",VLOOKUP($A37,Contexto!$S$8:$W$18,5,0))
A38: O4 | B38: =IF(VLOOKUP($A38,Contexto!$S$8:$W$18,2,0)=0,"",VLOOKUP($A38,Contexto!$S$8:$W$18,2,0)) | C38: =IF($B38="","",VLOOKUP($A38,BSD!$A$48:$B$87,2,0)) | D38: =IF(VLOOKUP($A38,Contexto!$S$8:$W$18,3,0)=0,"",VLOOKUP($A38,Contexto!$S$8:$W$18,3,0)) | E38: =IF(VLOOKUP($A38,Contexto!$S$8:$W$18,4,0)=0,"",VLOOKUP($A38,Contexto!$S$8:$W$18,4,0)) | F38: =IF(VLOOKUP($A38,Contexto!$S$8:$W$18,5,0)=0,"",VLOOKUP($A38,Contexto!$S$8:$W$18,5,0))
A39: O5 | B39: =IF(VLOOKUP($A39,Contexto!$S$8:$W$18,2,0)=0,"",VLOOKUP($A39,Contexto!$S$8:$W$18,2,0)) | C39: =IF($B39="","",VLOOKUP($A39,BSD!$A$48:$B$87,2,0)) | D39: =IF(VLOOKUP($A39,Contexto!$S$8:$W$18,3,0)=0,"",VLOOKUP($A39,Contexto!$S$8:$W$18,3,0)) | E39: =IF(VLOOKUP($A39,Contexto!$S$8:$W$18,4,0)=0,"",VLOOKUP($A39,Contexto!$S$8:$W$18,4,0)) | F39: =IF(VLOOKUP($A39,Contexto!$S$8:$W$18,5,0)=0,"",VLOOKUP($A39,Contexto!$S$8:$W$18,5,0))
A40: O6 | B40: =IF(VLOOKUP($A40,Contexto!$S$8:$W$18,2,0)=0,"",VLOOKUP($A40,Contexto!$S$8:$W$18,2,0)) | C40: =IF($B40="","",VLOOKUP($A40,BSD!$A$48:$B$87,2,0)) | D40: =IF(VLOOKUP($A40,Contexto!$S$8:$W$18,3,0)=0,"",VLOOKUP($A40,Contexto!$S$8:$W$18,3,0)) | E40: =IF(VLOOKUP($A40,Contexto!$S$8:$W$18,4,0)=0,"",VLOOKUP($A40,Contexto!$S$8:$W$18,4,0)) | F40: =IF(VLOOKUP($A40,Contexto!$S$8:$W$18,5,0)=0,"",VLOOKUP($A40,Contexto!$S$8:$W$18,5,0))
A41: O7 | B41: =IF(VLOOKUP($A41,Contexto!$S$8:$W$18,2,0)=0,"",VLOOKUP($A41,Contexto!$S$8:$W$18,2,0)) | C41: =IF($B41="","",VLOOKUP($A41,BSD!$A$48:$B$87,2,0)) | D41: =IF(VLOOKUP($A41,Contexto!$S$8:$W$18,3,0)=0,"",VLOOKUP($A41,Contexto!$S$8:$W$18,3,0)) | E41: =IF(VLOOKUP($A41,Contexto!$S$8:$W$18,4,0)=0,"",VLOOKUP($A41,Contexto!$S$8:$W$18,4,0)) | F41: =IF(VLOOKUP($A41,Contexto!$S$8:$W$18,5,0)=0,"",VLOOKUP($A41,Contexto!$S$8:$W$18,5,0))
...

Sheet Plan Táctico
A1: LOGO DE LA ORGANIZACIÓN | C1: NOMBRE DE LA ORGANIZACIÓN | D1: PLAN ESTRATÉGICO Y TÁCTICO | F1: CÓDIGO:
F3: VERSIÓN: 02
A6: Año(s) de proyección | C6: =_xlfn.CONCAT(Taller!$E$23,"-",Taller!$I$23) -> 2024-2027 | F6: Fecha de actualización | G6: 45200 | N6: Seguimiento al PE | P6: =Taller!$G$307 -> Semestral
F8: TÁCTICA(S) A REALIZAR (PHVA) PARA CUMPLIR LA (S) ESTRATEGIA (S) ¿CÓMO LO HAREMOS PARA CUMPLIR LA(S) ESTRATEGIA(S)? | I8: DURACIÓN ¿CUÁNTO DURA? | K8: PRESUPUESTO (Recursos necesarios) ¿CUÁNTO CUESTA? | N8: KPIS (Medición de la estrategia y/o tácticas) ¿CÓMO MEDIMOS LA ESTRATEGIA?
A9: No. | B9: PROCESO O ÁREA O COMPONENTE O SECCIÓN | C9: LINEA ESTRATÉGICA | D9: OBJETIVOS ¿QUÉ DESEAMOS LOGRAR? | E9: ESTRATEGIA(S) | F9: ACTIVIDADES A REALIZAR | G9: PRODUCTO | H9: RESPONSABLE (S) DE LA(S) TÁCTICA(S) ¿QUIÉN LO HARÁ? | I9: Fecha Programada | J9: =F9 -> ACTIVIDADES A REALIZAR | K9: CONCEPTO DEL RECURSO (Ejemplo: Recurso humano, financiero, papelería, tecnológico, etc.) | L9: RUBRO PRESUPUESTO (Valor en pesos aprox) | M9: Estrategia | N9: Nombre del indicador (KPI) | O9: Fórmula | P9: Meta | Q9: Frecuencia
A10: D1 | B10: =IF(A10="","",VLOOKUP($A10,'Matriz cruzada'!$A$4:$J$44,2,0)) -> Gestión del riesgo de turismo de aventura | C10: =IF(A10="","",VLOOKUP($A10,'Matriz cruzada'!$A$4:$J$44,8,0)) -> Gestión de procesos | D10: =IF(A10="","",VLOOKUP($A10,'Matriz cruzada'!$A$4:$J$44,9,0)) -> Mejorar la gestión de los procesos, aumentando la seguridad en nuestras operaciones al 95%. | E10: =IF(A10="","",VLOOKUP($A10,'Matriz cruzada'!$A$4:$J$44,10,0)) -> Documentar los procesos del sistema de gestión de turismo de aventura, para garantizar una buena planificación y gestión de las actividades de la agencia. | F10: Elaborar plan de trabajo para la documentación de los procesos. | G10: Plan de trabajo de documentación | H10: Líder del sistema de gestión de seguridad de turismo de aventura | I10: 45657 | J10: =F10 -> Elaborar plan de trabajo para la documentación de los procesos. | K10: Humano | L10: 2000000 | M10: =E10 -> Documentar los procesos del sistema de gestión de turismo de aventura, para garantizar una buena planificación y gestión de las actividades de la agencia. | N10: % Cumplimiento de plan de trabajo documentación | O10: (Actividades ejecutadas/Total actividades)*100% | P10: 0.9 | Q10: Semestral
A11: F1 | B11: =IF(A11="","",VLOOKUP($A11,'Matriz cruzada'!$A$4:$J$44,2,0)) -> Administrativo y Financiero | C11: =IF(A11="","",VLOOKUP($A11,'Matriz cruzada'!$A$4:$J$44,8,0)) -> Crecimiento | D11: =IF(A11="","",VLOOKUP($A11,'Matriz cruzada'!$A$4:$J$44,9,0)) -> Aumentar la ventas en 10% con respecto al año anterior | E11: =IF(A11="","",VLOOKUP($A11,'Matriz cruzada'!$A$4:$J$44,10,0)) -> Fortalecer la gestión comercial a través de la consecución de los recursos para las actividades de turismo y condiciones de talento humano. | F11: Capacitar al equipo comercial, brindando entrenamiento y recursos adecuados para que puedan ofrecer una experiencia excepcional al cliente. | G11: Plan de formación | H11: Director Administrativo y Financiero | I11: 45657 | J11: =F11 -> Capacitar al equipo comercial, brindando entrenamiento y recursos adecuados para que puedan ofrecer una experiencia excepcional al cliente. | K11: Humano | L11: 1000000 | M11: =E11 -> Fortalecer la gestión comercial a través de la consecución de los recursos para las actividades de turismo y condiciones de talento humano. | N11: % Cumplimiento de plan de formación | O11: (Actividades de formación ejecutadas/Total actividades de formación)*100% | P11: 0.9 | Q11: Semestral
A12: F2 | B12: =IF(A12="","",VLOOKUP($A12,'Matriz cruzada'!$A$4:$J$44,2,0)) -> Gestión Comercial | C12: =IF(A12="","",VLOOKUP($A12,'Matriz cruzada'!$A$4:$J$44,8,0)) -> Crecimiento | D12: =IF(A12="","",VLOOKUP($A12,'Matriz cruzada'!$A$4:$J$44,9,0)) -> Aumentar la ventas en 10% con respecto al año anterior | E12: =IF(A12="","",VLOOKUP($A12,'Matriz cruzada'!$A$4:$J$44,10,0)) -> Fortalecer la gestión comercial en turismo a través de la consecución de los recursos para las actividades de turismo y condiciones de talento humano. | F12: Desarrollar una propuesta de valor única, encontrando diferenciadores de la competencia destacando los beneficios y ventajas de los servicios de turismo de aventura, para lograr nuevas negociaciones. | G12: Nuevas ventas | H12: Líder del sistema de gestión de seguridad de turismo de aventura | I12: 45614 | J12: =F12 -> Desarrollar una propuesta de valor única, encontrando diferenciadores de la competencia destacando los beneficios y ventajas de los servicios de turismo de aventura, para lograr nuevas negociaciones. | K12: Humano | L12: 3000000 | M12: =E12 -> Fortalecer la gestión comercial en turismo a través de la consecución de los recursos para las actividades de turismo y condiciones de talento humano. | N12: Variación en ventas | O12: (Ventas presente año - Ventas año anterior) / Ventas año anterior ) * 100 | P12: 0.1 | Q12: Anual
A13: A2 | B13: =IF(A13="","",VLOOKUP($A13,'Matriz cruzada'!$A$4:$J$44,2,0)) -> Comunicación y consulta | C13: =IF(A13="","",VLOOKUP($A13,'Matriz cruzada'!$A$4:$J$44,8,0)) -> Crecimiento | D13: =IF(A13="","",VLOOKUP($A13,'Matriz cruzada'!$A$4:$J$44,9,0)) -> Implementar un plan de TI que contenga innovación durante el próximo año. | E13: =IF(A13="","",VLOOKUP($A13,'Matriz cruzada'!$A$4:$J$44,10,0)) -> Innovar y transformar nuestros servicios por medio del uso de plataformas de tecnología y canales digitales para ofertar los servicios. | F13: Implementar marketing digital, aprovechando las redes sociales, email marketing y otros canales digitales para llegar a nuevos clientes y fomentar las ventas. | G13: Nuevos leads en clientes | H13: Líder del sistema de gestión de seguridad de turismo de aventura | I13: 45614 | J13: =F13 -> Implementar marketing digital, aprovechando las redes sociales, email marketing y otros canales digitales para llegar a nuevos clientes y fomentar las ventas. | K13: Financiero | L13: 2500000 | M13: =E13 -> Innovar y transformar nuestros servicios por medio del uso de plataformas de tecnología y canales digitales para ofertar los servicios. | N13: Nuevos lead / red social | O13: Cantidad de leads por cada una de las redes sociales | P13: 3 | Q13: Semestral
B14: =IF(A14="","",VLOOKUP($A14,'Matriz cruzada'!$A$4:$J$44,2,0)) | C14: =IF(A14="","",VLOOKUP($A14,'Matriz cruzada'!$A$4:$J$44,8,0)) | D14: =IF(A14="","",VLOOKUP($A14,'Matriz cruzada'!$A$4:$J$44,9,0)) | E14: =IF(A14="","",VLOOKUP($A14,'Matriz cruzada'!$A$4:$J$44,10,0)) | J14: =F14 -> 0 | M14: =E14
B15: =IF(A15="","",VLOOKUP($A15,'Matriz cruzada'!$A$4:$J$44,2,0)) | C15: =IF(A15="","",VLOOKUP($A15,'Matriz cruzada'!$A$4:$J$44,8,0)) | D15: =IF(A15="","",VLOOKUP($A15,'Matriz cruzada'!$A$4:$J$44,9,0)) | E15: =IF(A15="","",VLOOKUP($A15,'Matriz cruzada'!$A$4:$J$44,10,0)) | J15: =F15 -> 0 | M15: =E15
B16: =IF(A16="","",VLOOKUP($A16,'Matriz cruzada'!$A$4:$J$44,2,0)) | C16: =IF(A16="","",VLOOKUP($A16,'Matriz cruzada'!$A$4:$J$44,8,0)) | D16: =IF(A16="","",VLOOKUP($A16,'Matriz cruzada'!$A$4:$J$44,9,0)) | E16: =IF(A16="","",VLOOKUP($A16,'Matriz cruzada'!$A$4:$J$44,10,0)) | J16: =F16 -> 0 | M16: =E16
B17: =IF(A17="","",VLOOKUP($A17,'Matriz cruzada'!$A$4:$J$44,2,0)) | C17: =IF(A17="","",VLOOKUP($A17,'Matriz cruzada'!$A$4:$J$44,8,0)) | D17: =IF(A17="","",VLOOKUP($A17,'Matriz cruzada'!$A$4:$J$44,9,0)) | E17: =IF(A17="","",VLOOKUP($A17,'Matriz cruzada'!$A$4:$J$44,10,0)) | J17: =F17 -> 0 | M17: =E17
B18: =IF(A18="","",VLOOKUP($A18,'Matriz cruzada'!$A$4:$J$44,2,0)) | C18: =IF(A18="","",VLOOKUP($A18,'Matriz cruzada'!$A$4:$J$44,8,0)) | D18: =IF(A18="","",VLOOKUP($A18,'Matriz cruzada'!$A$4:$J$44,9,0)) | E18: =IF(A18="","",VLOOKUP($A18,'Matriz cruzada'!$A$4:$J$44,10,0)) | J18: =F18 -> 0 | M18: =E18
B19: =IF(A19="","",VLOOKUP($A19,'Matriz cruzada'!$A$4:$J$44,2,0)) | C19: =IF(A19="","",VLOOKUP($A19,'Matriz cruzada'!$A$4:$J$44,8,0)) | D19: =IF(A19="","",VLOOKUP($A19,'Matriz cruzada'!$A$4:$J$44,9,0)) | E19: =IF(A19="","",VLOOKUP($A19,'Matriz cruzada'!$A$4:$J$44,10,0)) | J19: =F19 -> 0 | M19: =E19
B20: =IF(A20="","",VLOOKUP($A20,'Matriz cruzada'!$A$4:$J$44,2,0)) | C20: =IF(A20="","",VLOOKUP($A20,'Matriz cruzada'!$A$4:$J$44,8,0)) | D20: =IF(A20="","",VLOOKUP($A20,'Matriz cruzada'!$A$4:$J$44,9,0)) | E20: =IF(A20="","",VLOOKUP($A20,'Matriz cruzada'!$A$4:$J$44,10,0)) | J20: =F20 -> 0 | M20: =E20
B21: =IF(A21="","",VLOOKUP($A21,'Matriz cruzada'!$A$4:$J$44,2,0)) | C21: =IF(A21="","",VLOOKUP($A21,'Matriz cruzada'!$A$4:$J$44,8,0)) | D21: =IF(A21="","",VLOOKUP($A21,'Matriz cruzada'!$A$4:$J$44,9,0)) | E21: =IF(A21="","",VLOOKUP($A21,'Matriz cruzada'!$A$4:$J$44,10,0)) | J21: =F21 -> 0 | M21: =E21
B22: =IF(A22="","",VLOOKUP($A22,'Matriz cruzada'!$A$4:$J$44,2,0)) | C22: =IF(A22="","",VLOOKUP($A22,'Matriz cruzada'!$A$4:$J$44,8,0)) | D22: =IF(A22="","",VLOOKUP($A22,'Matriz cruzada'!$A$4:$J$44,9,0)) | E22: =IF(A22="","",VLOOKUP($A22,'Matriz cruzada'!$A$4:$J$44,10,0)) | J22: =F22 -> 0 | M22: =E22
B23: =IF(A23="","",VLOOKUP($A23,'Matriz cruzada'!$A$4:$J$44,2,0)) | C23: =IF(A23="","",VLOOKUP($A23,'Matriz cruzada'!$A$4:$J$44,8,0)) | D23: =IF(A23="","",VLOOKUP($A23,'Matriz cruzada'!$A$4:$J$44,9,0)) | E23: =IF(A23="","",VLOOKUP($A23,'Matriz cruzada'!$A$4:$J$44,10,0)) | J23: =F23 -> 0 | M23: =E23
B24: =IF(A24="","",VLOOKUP($A24,'Matriz cruzada'!$A$4:$J$44,2,0)) | C24: =IF(A24="","",VLOOKUP($A24,'Matriz cruzada'!$A$4:$J$44,8,0)) | D24: =IF(A24="","",VLOOKUP($A24,'Matriz cruzada'!$A$4:$J$44,9,0)) | E24: =IF(A24="","",VLOOKUP($A24,'Matriz cruzada'!$A$4:$J$44,10,0)) | J24: =F24 -> 0 | M24: =E24
B25: =IF(A25="","",VLOOKUP($A25,'Matriz cruzada'!$A$4:$J$44,2,0)) | C25: =IF(A25="","",VLOOKUP($A25,'Matriz cruzada'!$A$4:$J$44,8,0)) | D25: =IF(A25="","",VLOOKUP($A25,'Matriz cruzada'!$A$4:$J$44,9,0)) | E25: =IF(A25="","",VLOOKUP($A25,'Matriz cruzada'!$A$4:$J$44,10,0)) | J25: =F25 -> 0 | M25: =E25
... B49: =IF(A49="","",VLOOKUP($A49,'Matriz cruzada'!$A$4:$J$44,2,0)) | C49: =IF(A49="","",VLOOKUP($A49,'Matriz cruzada'!$A$4:$J$44,8,0)) | D49: =IF(A49="","",VLOOKUP($A49,'Matriz cruzada'!$A$4:$J$44,9,0)) | E49: =IF(A49="","",VLOOKUP($A49,'Matriz cruzada'!$A$4:$J$44,10,0)) | J49: =F49 -> 0 | M49: =E49
K50: Total presupuesto plan estratégico

Sheet Plan Estrategico
B2: PLAN ESTRATÉGICO EMPRESARIAL
B19: =Contexto!$H$5 -> TURISMO DE ADRENALINA
B32: =Taller!E23 -> 2024 | C32: - | D32: =Taller!I23 -> 2027
B40: =Taller!$F$16 -> 45504
B49: TABLA DE CONTENIDO
B52: 1 | C52: INTRODUCCIÓN | E52: =$B$95 -> 3
B54: 2 | C54: ¿QUÉ ES LA PLANEACIÓN ESTRATÉGICA? | E54: =B114 -> 4
B56: 3 | C56: ANÁLISIS DE CONTEXTO | E56: =B164 -> 6
B58: 4 | C58: ARTICULACIÓN CON PLANES DE DESARROLLO Y ODS | E58: =$B$234 -> 8
B60: 5 | C60: MISIÓN Y VISIÓN | E60: =$B$311 -> 10
B62: 6 | C62: LÍNEAS ESTRATÉGICAS Y ESTRATEGIAS | E62: =$B$325 -> 11
B64: 7 | C64: TÁCTICAS | E64: =$B$357 -> 13
B66: 8 | C66: PRESUPUESTO | E66: =$B$397 -> 15
B68: 9 | C68: INDICADORES | E68: =$B$424 -> 17
B70: 10 | C70: SEGUIMIENTO | E70: =$B$453 -> 19
B72: 11 | C72: BIBLIOGRAFÍA | E72: =$B$453 -> 19
B95: 3
B96: INTRODUCCIÓN
B98: La industria del turismo en Colombia ha experimentado un crecimiento significativo en los últimos años, convirtiéndose en un motor clave para el desarrollo económico y la promoción de la belleza de nuestro país. En este contexto de crecimiento y transformación, es esencial que los prestadores de servicios turísticos estén preparados para enfrentar los desafíos y aprovechar las oportunidades que se presentan. Este Plan Estratégico para los Prestadores de Servicios Turísticos en Colombia es un documento que busca proporcionar una guía clara y efectiva para elevar la calidad y seguridad en los servicios de turismo de aventura, fortalecer la competitividad y contribuir al posicionamiento de Colombia como un destino turístico de clase mundial. En este plan, se abordarán aspectos clave, como la mejora de la seguridad, la capacitación del personal y la adaptación a las cambiantes tendencias del mercado. A lo largo de este documento, se delinean objetivos específicos, estrategias y acciones concretas que permitirán a los prestadores de servicios turísticos en Colombia responder de manera efectiva a las demandas de los visitantes y brindar experiencias memorables. Este plan representa un compromiso con la excelencia en el servicio y la seguridad en el servicio. Juntos, trabajaremos para consolidar a Colombia como un destino turístico de renombre internacional, enriqueciendo la experiencia de quienes nos visitan y generando oportunidades para el desarrollo de nuestras regiones.
B113: 2. ¿QUÉ ES LA PLANEACIÓN ESTRATÉGICA?
B114: 4
B115: La Planificación Estratégica es un instrumento de gestión que permite favorecer y direccionar la toma de decisiones de las organizaciones, en torno a la operación actual y a la ruta que deben recorrer hacia el futuro. En este proceso se define el marco que guiará la filosofía, planes, actividades y recursos necesarios para el logro de las metas y propósitos en un determinado período, así como los mecanismos para su seguimiento y control, a fin de garantizar el cumplimiento. El Plan Estratégico de una empresa es un documento que detalla la manera en que tu negocio se va a desarrollar a corto, mediano y largo plazo. Este plan se basa en proyecciones cuantitativas y cualitativas para determinar cuáles son los paradigmas que la empresa debe seguir para lograr sus objetivos y aumentar su rentabilidad. La creación de un plan estratégico es un ejercicio que le permite a una organización saber qué quiere conseguir en el futuro y cómo lo va a lograr por medio de recursos, procedimientos y acciones. Para idear, proyectar, decidir y realizar los objetivos es necesario valerse de la experiencia y de herramientas cualitativas, como la investigación, la experiencia, el análisis de contexto, entre otras. Por el lado cuantitativo, es vital precisar cuáles son los recursos con lo que se cuenta para cumplir los objetivos. Es importante realizar un presupuesto maestro que abarque todos los aspectos necesarios para llevar a cabo tu plan estratégico. A la vez, es imprescindible fijar los tiempos para cada etapa del desarrollo. Cuanto más específico sea, mejor.
B116: El valor de un plan estratégico reside en determinar el rumbo de una empresa. Es un documento que establece las medidas futuras que se van a realizar para disminuir los riesgos e incertidumbre en el mercado. Una vez que esté clara la situación actual y cuáles son los próximos objetivos será mucho más fácil conducir a la organización a un crecimiento potencial. Además de indicar la dirección de una empresa, un plan estratégico sirve para detectar las oportunidades de negocio y aminorar considerablemente los factores negativos externos que puedan contrarrestar sus beneficios. De igual modo, este plan ayuda a impulsar las fortalezas de la organización y a reducir sus puntos débiles.
B118: =CONCATENATE("En el ",$B$19,", hemos definido los siguientes pasos para la elaboración de nuestro plan estratégico así:") -> En el TURISMO DE ADRENALINA, hemos definido los siguientes pasos para la elaboración de nuestro plan estratégico así:
B121: 5
B146: Cada uno de los pasos se explica a continuación:
B157: =CONCATENATE("En el ",$B$19,", se consideró un horizonte de tiempo del plan estratégico (PE) de ",$B$32," , debido a que se quieren acciones a corto plazo, como causa de los cambios constantes de la economía, cambio climático y otras causas a nivel local, nacional, regional y mundial.") -> En el TURISMO DE ADRENALINA, se consideró un horizonte de tiempo del plan estratégico (PE) de 2024 , debido a que se quieren acciones a corto plazo, como causa de los cambios constantes de la economía, cambio climático y otras causas a nivel local, nacional, regional y mundial.
B164: 6
B166: =CONCATENATE("En el ",$B$19,", se realizó un análisis de contexto interno y externo mediante la identificación de la actores internos positivos, factores internos negativos, factores externos positivos y factores externos negativos; "," que contribuyó a examinar los procesos internos e investigar qué está pasando alrededor y ahondar en los asuntos",". Esto se construyó con el aporte de cada uno de los colaboradores de la organización, aportando de su rol desde cada una de áreas de la empresa.") -> En el TURISMO DE ADRENALINA, se realizó un análisis de contexto interno y externo mediante la identificación de la actores internos positivos, factores internos negativos, factores externos positivos y factores externos negativos; que contribuyó a examinar los procesos internos e investigar qué está pasando alrededor y ahondar en los asuntos. Esto se construyó con el aporte de cada uno de los colaboradores de la organización, aportando de su rol desde cada una de áreas de la empresa.
B200: En el análisis de contexto interno y externo se identificó:
B202: 7
B203: ANÁLISIS INTERNO
B204: Factores Internos Negativos | D204: Factores Internos Positivos
B205: =IF('Matriz cruzada'!$E5=0,"",'Matriz cruzada'!$E5) -> Mala planeación para la realización de las actividades de turismo de aventura. | D205: =IF('Matriz cruzada'!$E15=0,"",'Matriz cruzada'!$E15) -> Personal capacitado excelente para atención al cliente
B206: =IF('Matriz cruzada'!$E6=0,"",'Matriz cruzada'!$E6) -> No cuentan con canales de comunicación asertiva. | D206: =IF('Matriz cruzada'!$E16=0,"",'Matriz cruzada'!$E16) -> Experiencia en turismo de aventura
B207: =IF('Matriz cruzada'!$E7=0,"",'Matriz cruzada'!$E7) | D207: =IF('Matriz cruzada'!$E17=0,"",'Matriz cruzada'!$E17)
B208: =IF('Matriz cruzada'!$E8=0,"",'Matriz cruzada'!$E8) | D208: =IF('Matriz cruzada'!$E18=0,"",'Matriz cruzada'!$E18)
B209: =IF('Matriz cruzada'!$E9=0,"",'Matriz cruzada'!$E9) | D209: =IF('Matriz cruzada'!$E19=0,"",'Matriz cruzada'!$E19)
B210: =IF('Matriz cruzada'!$E10=0,"",'Matriz cruzada'!$E10) | D210: =IF('Matriz cruzada'!$E20=0,"",'Matriz cruzada'!$E20)
B211: =IF('Matriz cruzada'!$E11=0,"",'Matriz cruzada'!$E11) | D211: =IF('Matriz cruzada'!$E21=0,"",'Matriz cruzada'!$E21)
...

Sheet Estrategias
A1: Turismo sostenible | B1: Fomentar el turismo de proximidad: Promover destinos turísticos cercanos a las comunidades locales y destacar las actividades que los viajeros pueden disfrutar sin dejar una huella significativa de carbono. Esto reduce la necesidad de viajar largas distancias y apoya a las empresas locales.
A2: Turismo sostenible | B2: Educación ambiental y cultural: Ofrecer información a los visitantes sobre la flora, fauna y cultura local, incentivando el respeto por el entorno y las tradiciones. Puedes organizar excursiones guiadas por expertos locales que compartan su conocimiento y pasión.
A3: Turismo sostenible | B3: Promoción del transporte sostenible: Fomentar el uso del transporte público, bicicletas o caminatas para moverse dentro del destino. También se pueden ofrecer incentivos, como descuentos, para quienes utilicen opciones de transporte más ecológicas.
A4: Turismo sostenible | B4: Uso eficiente de recursos: Implementar prácticas de gestión sostenible, como la reducción de desperdicio de agua y energía en las instalaciones turísticas, la separación de residuos y el fomento de la compra de productos locales y orgánicos.
A5: Turismo sostenible | B5: Apoyo a proyectos comunitarios: Colaborar con comunidades locales para desarrollar proyectos turísticos que beneficien directamente a la población local. Esto puede incluir la creación de cooperativas de artesanías, restaurantes con cocina local o actividades culturales que generen ingresos para las comunidades.
A6: Estandarización de procesos | B6: Documentación de procesos: Crea documentos detallados que describan cada paso de los procesos clave en tu organización. Utiliza diagramas de flujo, manuales o listas de verificación para asegurarte de que todos comprendan cómo se deben llevar a cabo las tareas.
A7: Estandarización de procesos | B7: Formación y capacitación: Proporciona capacitación adecuada a los empleados sobre los procedimientos estandarizados. Asegúrate de que todos tengan acceso a la información y el entrenamiento necesarios para llevar a cabo sus funciones de manera efectiva.
A8: Estandarización de procesos | B8: Comunicación clara: Establece canales de comunicación efectivos para asegurarte de que todos los miembros del equipo estén al tanto de los cambios en los procesos y las actualizaciones en la documentación. Esto incluye reuniones regulares, correos electrónicos informativos y un sistema de gestión de cambios claro.
A9: Estandarización de procesos | B9: Automatización de tareas repetitivas: Identifica tareas que se repiten con frecuencia y busca soluciones tecnológicas o herramientas de software que puedan automatizarlas. Esto reduce la probabilidad de errores humanos y acelera la ejecución de procesos.
A10: Estandarización de procesos | B10: Evaluación y mejora continua: Establece indicadores clave de rendimiento (KPI) para medir la eficiencia y la calidad de los procesos. Realiza evaluaciones periódicas y fomenta la retroalimentación de los empleados para identificar áreas de mejora. A partir de esto, ajusta y actualiza los procedimientos según sea necesario.
A11: Transformación Digital | B11: Implementación de herramientas de colaboración en línea: Utiliza herramientas como Microsoft Teams, Slack o Trello para facilitar la comunicación y colaboración entre los miembros del equipo, incluso si trabajan de forma remota. Esto mejora la eficiencia y la flexibilidad en el trabajo.
A12: Transformación Digital | B12: Presencia en línea y redes sociales: Crea y actualiza un sitio web atractivo y optimizado para dispositivos móviles. Además, establece una presencia activa en las redes sociales relevantes para tu industria. Esto te permitirá llegar a un público más amplio y mantener a tus clientes informados.
... A30: Requisitos Legales | B30: Mantenimiento de registros financieros: Lleva registros financieros precisos y bien organizados. Esto es fundamental para cumplir con los requisitos fiscales y contables, y facilitará la auditoría y la presentación de informes necesarios.
B36: Construir la propuesta de valor corporativa e impulsarla ante clientes actuales y potenciales
B40: Desarrollar alianzas estratégicas con otras empresas o agremiaciones o similar
B45: Desarrollar nuevos servicios o unidades de negocios
B50: Análisis de Mercado y Monitoreo de la competencia (Benchmarking)
